Workbook

Sheet Ruas
A1: ID | B1: Day | C1: Kawasan | D1: Pencatat | E1: Tanggal | F1: Jam | G1: Nama ruas | H1: Panjang ruas (m) | I1: Jenis jalan | J1: Kepadatan kendaraan | K1: Trotoar | L1: Lebar Trotoar (m) | M1: Lebar Jalan (m) | N1: Panjang trotoar terputus (m) | O1: Penghalang utama | P1: Jumlah lubang atau paving lepas | Q1: Pejalan turun ke jalan | R1: Jumlah zebra cross | S1: Jumlah jembatan penyeberangan | T1: Jumlah tiang lampu | U1: Jumlah lampu rusak fisik | V1: Jarak antar tiang (m) | W1: Keteduhan | X1: Waktu melintas ruas (detik) | Y1: Jumlah foto | Z1: Catatan | AA1: Muat mobil (unit) | AB1: Kecepatan implisit (m/s) | AC1: I-1 ketersediaan | AD1: I-2 lebar | AE1: I-3 keutuhan | AF1: I-4 kemulusan | AG1: I-5 tidak turun | AH1: Bobot terpakai | AI1: W-6 integritas | AJ1: W-6 status
A2: RUAS-001 | B2: Day 1 | C2: KWS-06 | D2: Delon | E2: 2026-08-16 | F2: 11:02 | G2: Jl. Besi Jangkang, Gg. bougenvile | H2: 110 | I2: Gang | J2: Sepi | K2: Tidak ada | L2: 0 | M2: 3 | N2: 0 | O2: tidak ada | P2: 0 | Q2: Tidak | R2: 0 | S2: 0 | T2: 7 | U2: 1 | V2: 20 | W2: Di bawah 25 persen | X2: 109 | Y2: 2 | Z2: Mendekati tanggal kemerdekaan, banyak hiasan bendera. Kondisi jalan rata. Keteduhan sangat minim. Jalan paving. | AA2: 1 | AB2: 1.01 | AC2: =IF($K2="","",IF($K2="Ada",1,IF($K2="Sebagian",0.5,0))) | AD2: =IF($K2="","",IF($K2="Tidak ada",0,IF($L2="","",MIN($L2/Panduan_W6!$B$9,1)))) | AE2: =IF($K2="","",IF($K2="Tidak ada",0,IF(OR($N2="",$H2=""),"",MAX(0,1-$N2/$H2)))) | AF2: =IF(OR($K2="",$K2="Tidak ada"),"",IF(OR($P2="",$H2=""),"",EXP(-$P2/$H2*100/Panduan_W6!$B$10))) | AG2: =IF($Q2="","",IF($Q2="Tidak",1,0)) | AH2: =IF(ISNUMBER(AC2),Panduan_W6!$B$4,0)+IF(ISNUMBER(AD2),Panduan_W6!$B$5,0)+IF(ISNUMBER(AE2),Panduan_W6!$B$6,0)+IF(ISNUMBER(AF2),Panduan_W6!$B$7,0)+IF(ISNUMBER(AG2),Panduan_W6!$B$8,0) | AI2: =IF(LEFT(AJ2,7)<>"Lengkap","",IF(AJ2="Lengkap (gang)",AG2,(IF(ISNUMBER(AC2),Panduan_W6!$B$4*AC2,0)+IF(ISNUMBER(AD2),Panduan_W6!$B$5*AD2,0)+IF(ISNUMBER(AE2),Panduan_W6!$B$6*AE2,0)+IF(ISNUMBER(AF2),Panduan_W6!$B$7*AF2,0)+IF(ISNUMBER(AG2),Panduan_W6!$B$8*AG2,0))/AH2)) | AJ2: =IF(AND(Panduan_W6!$B$11="Ya",$I2="Gang",$J2="Sepi"),IF(ISNUMBER(AG2),"Lengkap (gang)","Belum lengkap"),IF(AND(ISNUMBER(AC2),ISNUMBER(AD2),ISNUMBER(AE2),ISNUMBER(AG2),OR(ISNUMBER(AF2),$K2="Tidak ada")),"Lengkap","Belum lengkap"))
A3: RUAS-002 | B3: Day 1 | C3: KWS-06 | D3: Andalan | E3: 2026-08-16 | F3: 11:28 | H3: 87 | I3: Gang | J3: Sepi | K3: Tidak ada | L3: 0 | M3: 3.7 | N3: 0 | O3: tidak ada | P3: 1 | Q3: Ya | R3: 0 | S3: 0 | T3: 3 | U3: 0 | V3: 18 | W3: Di bawah 25 persen | X3: 72 | Y3: 2 | Z3: Sedang ada pembangunan di Selatan gang sehingga banyak kerikil dan sampah di sisi jalan. | AA3: 1 | AB3: 1.21 | AC3: =IF($K3="","",IF($K3="Ada",1,IF($K3="Sebagian",0.5,0))) | AD3: =IF($K3="","",IF($K3="Tidak ada",0,IF($L3="","",MIN($L3/Panduan_W6!$B$9,1)))) | AE3: =IF($K3="","",IF($K3="Tidak ada",0,IF(OR($N3="",$H3=""),"",MAX(0,1-$N3/$H3)))) | AF3: =IF(OR($K3="",$K3="Tidak ada"),"",IF(OR($P3="",$H3=""),"",EXP(-$P3/$H3*100/Panduan_W6!$B$10))) | AG3: =IF($Q3="","",IF($Q3="Tidak",1,0)) | AH3: =IF(ISNUMBER(AC3),Panduan_W6!$B$4,0)+IF(ISNUMBER(AD3),Panduan_W6!$B$5,0)+IF(ISNUMBER(AE3),Panduan_W6!$B$6,0)+IF(ISNUMBER(AF3),Panduan_W6!$B$7,0)+IF(ISNUMBER(AG3),Panduan_W6!$B$8,0) | AI3: =IF(LEFT(AJ3,7)<>"Lengkap","",IF(AJ3="Lengkap (gang)",AG3,(IF(ISNUMBER(AC3),Panduan_W6!$B$4*AC3,0)+IF(ISNUMBER(AD3),Panduan_W6!$B$5*AD3,0)+IF(ISNUMBER(AE3),Panduan_W6!$B$6*AE3,0)+IF(ISNUMBER(AF3),Panduan_W6!$B$7*AF3,0)+IF(ISNUMBER(AG3),Panduan_W6!$B$8*AG3,0))/AH3)) | AJ3: =IF(AND(Panduan_W6!$B$11="Ya",$I3="Gang",$J3="Sepi"),IF(ISNUMBER(AG3),"Lengkap (gang)","Belum lengkap"),IF(AND(ISNUMBER(AC3),ISNUMBER(AD3),ISNUMBER(AE3),ISNUMBER(AG3),OR(ISNUMBER(AF3),$K3="Tidak ada")),"Lengkap","Belum lengkap"))
A4: RUAS-003 | B4: Day 1 | C4: KWS-06 | D4: Devon | E4: 2026-08-16 | F4: 11:33 | G4: Jl. Besi Jangkang, Gg. bougenvile | H4: 110 | I4: Gang | J4: Sepi | K4: Tidak ada | L4: 0 | M4: 4.5 | N4: 0 | O4: tidak ada | P4: 0 | Q4: Tidak | R4: 0 | S4: 0 | T4: 4 | U4: 0 | V4: 27.5 | W4: Nihil | X4: 107 | Y4: 2 | Z4: Terusan dari ruas jalan 001. Bantak hiasan tujuhbelasan. Jalan aspal, datar. Keteduhan nihil. | AA4: 1 | AB4: 1.03 | AC4: =IF($K4="","",IF($K4="Ada",1,IF($K4="Sebagian",0.5,0))) | AD4: =IF($K4="","",IF($K4="Tidak ada",0,IF($L4="","",MIN($L4/Panduan_W6!$B$9,1)))) | AE4: =IF($K4="","",IF($K4="Tidak ada",0,IF(OR($N4="",$H4=""),"",MAX(0,1-$N4/$H4)))) | AF4: =IF(OR($K4="",$K4="Tidak ada"),"",IF(OR($P4="",$H4=""),"",EXP(-$P4/$H4*100/Panduan_W6!$B$10))) | AG4: =IF($Q4="","",IF($Q4="Tidak",1,0)) | AH4: =IF(ISNUMBER(AC4),Panduan_W6!$B$4,0)+IF(ISNUMBER(AD4),Panduan_W6!$B$5,0)+IF(ISNUMBER(AE4),Panduan_W6!$B$6,0)+IF(ISNUMBER(AF4),Panduan_W6!$B$7,0)+IF(ISNUMBER(AG4),Panduan_W6!$B$8,0) | AI4: =IF(LEFT(AJ4,7)<>"Lengkap","",IF(AJ4="Lengkap (gang)",AG4,(IF(ISNUMBER(AC4),Panduan_W6!$B$4*AC4,0)+IF(ISNUMBER(AD4),Panduan_W6!$B$5*AD4,0)+IF(ISNUMBER(AE4),Panduan_W6!$B$6*AE4,0)+IF(ISNUMBER(AF4),Panduan_W6!$B$7*AF4,0)+IF(ISNUMBER(AG4),Panduan_W6!$B$8*AG4,0))/AH4)) | AJ4: =IF(AND(Panduan_W6!$B$11="Ya",$I4="Gang",$J4="Sepi"),IF(ISNUMBER(AG4),"Lengkap (gang)","Belum lengkap"),IF(AND(ISNUMBER(AC4),ISNUMBER(AD4),ISNUMBER(AE4),ISNUMBER(AG4),OR(ISNUMBER(AF4),$K4="Tidak ada")),"Lengkap","Belum lengkap"))
A5: RUAS-004 | B5: Day 1 | C5: KWS-06 | D5: Andalan | E5: 2026-08-16 | F5: 12:03 | G5: Jl. Kaliurang Km 12 | H5: 80 | I5: Jalan raya | J5: Ramai | K5: Tidak ada | L5: 0 | M5: 8 | N5: 0 | O5: tiang listrik | P5: 4 | Q5: Tidak | R5: 0 | S5: 0 | T5: 3 | U5: 0 | V5: 40 | W5: Nihil | X5: 72 | Y5: 1 | Z5: Sangat sulit berjalan kaki di samping jalan raya ini, pinggir jalan berlubang, berbatu, tidak rata. Tidak ada peneduhan dan minim penerangan. Banyak warung dan aktivitas ekonomi | AA5: 2 | AB5: 1.11 | AC5: =IF($K5="","",IF($K5="Ada",1,IF($K5="Sebagian",0.5,0))) | AD5: =IF($K5="","",IF($K5="Tidak ada",0,IF($L5="","",MIN($L5/Panduan_W6!$B$9,1)))) | AE5: =IF($K5="","",IF($K5="Tidak ada",0,IF(OR($N5="",$H5=""),"",MAX(0,1-$N5/$H5)))) | AF5: =IF(OR($K5="",$K5="Tidak ada"),"",IF(OR($P5="",$H5=""),"",EXP(-$P5/$H5*100/Panduan_W6!$B$10))) | AG5: =IF($Q5="","",IF($Q5="Tidak",1,0)) | AH5: =IF(ISNUMBER(AC5),Panduan_W6!$B$4,0)+IF(ISNUMBER(AD5),Panduan_W6!$B$5,0)+IF(ISNUMBER(AE5),Panduan_W6!$B$6,0)+IF(ISNUMBER(AF5),Panduan_W6!$B$7,0)+IF(ISNUMBER(AG5),Panduan_W6!$B$8,0) | AI5: =IF(LEFT(AJ5,7)<>"Lengkap","",IF(AJ5="Lengkap (gang)",AG5,(IF(ISNUMBER(AC5),Panduan_W6!$B$4*AC5,0)+IF(ISNUMBER(AD5),Panduan_W6!$B$5*AD5,0)+IF(ISNUMBER(AE5),Panduan_W6!$B$6*AE5,0)+IF(ISNUMBER(AF5),Panduan_W6!$B$7*AF5,0)+IF(ISNUMBER(AG5),Panduan_W6!$B$8*AG5,0))/AH5)) | AJ5: =IF(AND(Panduan_W6!$B$11="Ya",$I5="Gang",$J5="Sepi"),IF(ISNUMBER(AG5),"Lengkap (gang)","Belum lengkap"),IF(AND(ISNUMBER(AC5),ISNUMBER(AD5),ISNUMBER(AE5),ISNUMBER(AG5),OR(ISNUMBER(AF5),$K5="Tidak ada")),"Lengkap","Belum lengkap"))
A6: RUAS-005 | B6: Day 1 | C6: KWS-06 | D6: Andalan | E6: 2026-08-16 | F6: 13:28 | G6: Jl. Kaliurang Km 13 | H6: 90 | I6: Jalan raya | J6: Ramai | K6: Tidak ada | L6: 0 | M6: 8 | N6: 0 | O6: tiang listrik | P6: 7 | Q6: Tidak | R6: 0 | S6: 0 | T6: 1 | U6: 0 | V6: 0 | W6: Nihil | X6: 105 | Y6: 1 | Z6: Sangat banyak lobang, hanya 1 lampu, tidak ada zebra cross padahal sangat ramai | AA6: 2 | AB6: 0.86 | AC6: =IF($K6="","",IF($K6="Ada",1,IF($K6="Sebagian",0.5,0))) | AD6: =IF($K6="","",IF($K6="Tidak ada",0,IF($L6="","",MIN($L6/Panduan_W6!$B$9,1)))) | AE6: =IF($K6="","",IF($K6="Tidak ada",0,IF(OR($N6="",$H6=""),"",MAX(0,1-$N6/$H6)))) | AF6: =IF(OR($K6="",$K6="Tidak ada"),"",IF(OR($P6="",$H6=""),"",EXP(-$P6/$H6*100/Panduan_W6!$B$10))) | AG6: =IF($Q6="","",IF($Q6="Tidak",1,0)) | AH6: =IF(ISNUMBER(AC6),Panduan_W6!$B$4,0)+IF(ISNUMBER(AD6),Panduan_W6!$B$5,0)+IF(ISNUMBER(AE6),Panduan_W6!$B$6,0)+IF(ISNUMBER(AF6),Panduan_W6!$B$7,0)+IF(ISNUMBER(AG6),Panduan_W6!$B$8,0) | AI6: =IF(LEFT(AJ6,7)<>"Lengkap","",IF(AJ6="Lengkap (gang)",AG6,(IF(ISNUMBER(AC6),Panduan_W6!$B$4*AC6,0)+IF(ISNUMBER(AD6),Panduan_W6!$B$5*AD6,0)+IF(ISNUMBER(AE6),Panduan_W6!$B$6*AE6,0)+IF(ISNUMBER(AF6),Panduan_W6!$B$7*AF6,0)+IF(ISNUMBER(AG6),Panduan_W6!$B$8*AG6,0))/AH6)) | AJ6: =IF(AND(Panduan_W6!$B$11="Ya",$I6="Gang",$J6="Sepi"),IF(ISNUMBER(AG6),"Lengkap (gang)","Belum lengkap"),IF(AND(ISNUMBER(AC6),ISNUMBER(AD6),ISNUMBER(AE6),ISNUMBER(AG6),OR(ISNUMBER(AF6),$K6="Tidak ada")),"Lengkap","Belum lengkap"))
A7: RUAS-006 | B7: Day 1 | C7: KWS-06 | D7: Delon | E7: 2026-08-16 | F7: 13:38 | G7: Jl. Kaliurang Km 13 | H7: 110 | I7: Jalan raya | J7: Ramai | K7: Tidak ada | L7: 0 | M7: 8 | N7: 0 | O7: tiang listrik, lampu lalu lintas | P7: 7 | Q7: Tidak | R7: 0 | S7: 0 | T7: 3 | U7: 0 | V7: 40 | W7: Nihil | X7: 108 | Y7: 3 | Z7: jalan berlubang, perlu menyeberang gang karena ada pertigaan, tiang lampu merah menghalangi jalan, tidak ada zebracross | AA7: 2 | AB7: 1.02 | AC7: =IF($K7="","",IF($K7="Ada",1,IF($K7="Sebagian",0.5,0))) | AD7: =IF($K7="","",IF($K7="Tidak ada",0,IF($L7="","",MIN($L7/Panduan_W6!$B$9,1)))) | AE7: =IF($K7="","",IF($K7="Tidak ada",0,IF(OR($N7="",$H7=""),"",MAX(0,1-$N7/$H7)))) | AF7: =IF(OR($K7="",$K7="Tidak ada"),"",IF(OR($P7="",$H7=""),"",EXP(-$P7/$H7*100/Panduan_W6!$B$10))) | AG7: =IF($Q7="","",IF($Q7="Tidak",1,0)) | AH7: =IF(ISNUMBER(AC7),Panduan_W6!$B$4,0)+IF(ISNUMBER(AD7),Panduan_W6!$B$5,0)+IF(ISNUMBER(AE7),Panduan_W6!$B$6,0)+IF(ISNUMBER(AF7),Panduan_W6!$B$7,0)+IF(ISNUMBER(AG7),Panduan_W6!$B$8,0) | AI7: =IF(LEFT(AJ7,7)<>"Lengkap","",IF(AJ7="Lengkap (gang)",AG7,(IF(ISNUMBER(AC7),Panduan_W6!$B$4*AC7,0)+IF(ISNUMBER(AD7),Panduan_W6!$B$5*AD7,0)+IF(ISNUMBER(AE7),Panduan_W6!$B$6*AE7,0)+IF(ISNUMBER(AF7),Panduan_W6!$B$7*AF7,0)+IF(ISNUMBER(AG7),Panduan_W6!$B$8*AG7,0))/AH7)) | AJ7: =IF(AND(Panduan_W6!$B$11="Ya",$I7="Gang",$J7="Sepi"),IF(ISNUMBER(AG7),"Lengkap (gang)","Belum lengkap"),IF(AND(ISNUMBER(AC7),ISNUMBER(AD7),ISNUMBER(AE7),ISNUMBER(AG7),OR(ISNUMBER(AF7),$K7="Tidak ada")),"Lengkap","Belum lengkap"))
A8: RUAS-007 | B8: Day 1 | C8: KWS-06 | D8: Delon | E8: 2026-08-16 | F8: 13:49 | G8: Jl. Kaliurang Km 13 | H8: 140 | I8: Jalan raya | J8: Ramai | K8: Tidak ada | L8: 0 | M8: 8 | N8: 0 | O8: tidak ada | P8: 1 | Q8: Tidak | R8: 0 | S8: 0 | T8: 2 | U8: 0 | V8: 57 | W8: Nihil | X8: 90 | Y8: 1 | Z8: ruas pejalan kaki beton, tidak berlubang tidak ada zebra cross, tidak ada pohon, area pejalan kaki cukup lebar 2-3 orang | AA8: 2 | AB8: 1.56 | AC8: =IF($K8="","",IF($K8="Ada",1,IF($K8="Sebagian",0.5,0))) | AD8: =IF($K8="","",IF($K8="Tidak ada",0,IF($L8="","",MIN($L8/Panduan_W6!$B$9,1)))) | AE8: =IF($K8="","",IF($K8="Tidak ada",0,IF(OR($N8="",$H8=""),"",MAX(0,1-$N8/$H8)))) | AF8: =IF(OR($K8="",$K8="Tidak ada"),"",IF(OR($P8="",$H8=""),"",EXP(-$P8/$H8*100/Panduan_W6!$B$10))) | AG8: =IF($Q8="","",IF($Q8="Tidak",1,0)) | AH8: =IF(ISNUMBER(AC8),Panduan_W6!$B$4,0)+IF(ISNUMBER(AD8),Panduan_W6!$B$5,0)+IF(ISNUMBER(AE8),Panduan_W6!$B$6,0)+IF(ISNUMBER(AF8),Panduan_W6!$B$7,0)+IF(ISNUMBER(AG8),Panduan_W6!$B$8,0) | AI8: =IF(LEFT(AJ8,7)<>"Lengkap","",IF(AJ8="Lengkap (gang)",AG8,(IF(ISNUMBER(AC8),Panduan_W6!$B$4*AC8,0)+IF(ISNUMBER(AD8),Panduan_W6!$B$5*AD8,0)+IF(ISNUMBER(AE8),Panduan_W6!$B$6*AE8,0)+IF(ISNUMBER(AF8),Panduan_W6!$B$7*AF8,0)+IF(ISNUMBER(AG8),Panduan_W6!$B$8*AG8,0))/AH8)) | AJ8: =IF(AND(Panduan_W6!$B$11="Ya",$I8="Gang",$J8="Sepi"),IF(ISNUMBER(AG8),"Lengkap (gang)","Belum lengkap"),IF(AND(ISNUMBER(AC8),ISNUMBER(AD8),ISNUMBER(AE8),ISNUMBER(AG8),OR(ISNUMBER(AF8),$K8="Tidak ada")),"Lengkap","Belum lengkap"))
A9: RUAS-008 | B9: Day 1 | C9: KWS-11 | D9: Andalan | E9: 2026-08-16 | F9: 15:28 | G9: Gg. Pandega Rini I, Manggung, Caturtunggal | H9: 98 | I9: Gang | J9: Sepi | K9: Tidak ada | L9: 0 | M9: 3.3 | N9: 0 | O9: tidak ada | P9: 0 | Q9: Tidak | R9: 0 | S9: 0 | T9: 5 | U9: 1 | V9: 21 | W9: 25 sampai 50 persen | X9: 90 | Y9: 1 | Z9: Jalan kompleks perumahan, keluarnya tepat di Ringroad Utara. Jalan cukup oke, portal dibuka jam 5 sampai 22 | AA9: 1 | AB9: 1.09 | AC9: =IF($K9="","",IF($K9="Ada",1,IF($K9="Sebagian",0.5,0))) | AD9: =IF($K9="","",IF($K9="Tidak ada",0,IF($L9="","",MIN($L9/Panduan_W6!$B$9,1)))) | AE9: =IF($K9="","",IF($K9="Tidak ada",0,IF(OR($N9="",$H9=""),"",MAX(0,1-$N9/$H9)))) | AF9: =IF(OR($K9="",$K9="Tidak ada"),"",IF(OR($P9="",$H9=""),"",EXP(-$P9/$H9*100/Panduan_W6!$B$10))) | AG9: =IF($Q9="","",IF($Q9="Tidak",1,0)) | AH9: =IF(ISNUMBER(AC9),Panduan_W6!$B$4,0)+IF(ISNUMBER(AD9),Panduan_W6!$B$5,0)+IF(ISNUMBER(AE9),Panduan_W6!$B$6,0)+IF(ISNUMBER(AF9),Panduan_W6!$B$7,0)+IF(ISNUMBER(AG9),Panduan_W6!$B$8,0) | AI9: =IF(LEFT(AJ9,7)<>"Lengkap","",IF(AJ9="Lengkap (gang)",AG9,(IF(ISNUMBER(AC9),Panduan_W6!$B$4*AC9,0)+IF(ISNUMBER(AD9),Panduan_W6!$B$5*AD9,0)+IF(ISNUMBER(AE9),Panduan_W6!$B$6*AE9,0)+IF(ISNUMBER(AF9),Panduan_W6!$B$7*AF9,0)+IF(ISNUMBER(AG9),Panduan_W6!$B$8*AG9,0))/AH9)) | AJ9: =IF(AND(Panduan_W6!$B$11="Ya",$I9="Gang",$J9="Sepi"),IF(ISNUMBER(AG9),"Lengkap (gang)","Belum lengkap"),IF(AND(ISNUMBER(AC9),ISNUMBER(AD9),ISNUMBER(AE9),ISNUMBER(AG9),OR(ISNUMBER(AF9),$K9="Tidak ada")),"Lengkap","Belum lengkap"))
A10: RUAS-009 | B10: Day 1 | C10: KWS-11 | D10: Theo | E10: 2026-08-16 | F10: 15:42 | G10: Jl. Ringroad Utara | H10: 165.64 | I10: Jalan raya | J10: Sedang | K10: Ada | L10: 1.2 | M10: 5.25 | N10: 100.98 | O10: tidak ada | P10: 0 | Q10: Ya | R10: 0 | S10: 0 | T10: 5 | U10: 0 | V10: 19.37 | W10: Nihil | X10: 150 | Z10: jalanya dah bagus hanya beberapa ada penutup got yang berbahaya karena tidak rata | AA10: 2 | AB10: 1.1 | AC10: =IF($K10="","",IF($K10="Ada",1,IF($K10="Sebagian",0.5,0))) | AD10: =IF($K10="","",IF($K10="Tidak ada",0,IF($L10="","",MIN($L10/Panduan_W6!$B$9,1)))) | AE10: =IF($K10="","",IF($K10="Tidak ada",0,IF(OR($N10="",$H10=""),"",MAX(0,1-$N10/$H10)))) | AF10: =IF(OR($K10="",$K10="Tidak ada"),"",IF(OR($P10="",$H10=""),"",EXP(-$P10/$H10*100/Panduan_W6!$B$10))) | AG10: =IF($Q10="","",IF($Q10="Tidak",1,0)) | AH10: =IF(ISNUMBER(AC10),Panduan_W6!$B$4,0)+IF(ISNUMBER(AD10),Panduan_W6!$B$5,0)+IF(ISNUMBER(AE10),Panduan_W6!$B$6,0)+IF(ISNUMBER(AF10),Panduan_W6!$B$7,0)+IF(ISNUMBER(AG10),Panduan_W6!$B$8,0) | AI10: =IF(LEFT(AJ10,7)<>"Lengkap","",IF(AJ10="Lengkap (gang)",AG10,(IF(ISNUMBER(AC10),Panduan_W6!$B$4*AC10,0)+IF(ISNUMBER(AD10),Panduan_W6!$B$5*AD10,0)+IF(ISNUMBER(AE10),Panduan_W6!$B$6*AE10,0)+IF(ISNUMBER(AF10),Panduan_W6!$B$7*AF10,0)+IF(ISNUMBER(AG10),Panduan_W6!$B$8*AG10,0))/AH10)) | AJ10: =IF(AND(Panduan_W6!$B$11="Ya",$I10="Gang",$J10="Sepi"),IF(ISNUMBER(AG10),"Lengkap (gang)","Belum lengkap"),IF(AND(ISNUMBER(AC10),ISNUMBER(AD10),ISNUMBER(AE10),ISNUMBER(AG10),OR(ISNUMBER(AF10),$K10="Tidak ada")),"Lengkap","Belum lengkap"))
A11: RUAS-010 | B11: Day 1 | C11: KWS-04 | D11: Delon | E11: 2026-08-16 | F11: 15:52 | G11: Jl. Raya Tajem | H11: 140 | I11: Jalan raya | J11: Ramai | K11: Ada | L11: 1 | M11: 10 | N11: 0.5 | O11: mobil parkir | P11: 1 | Q11: Ya | R11: 0 | S11: 0 | T11: 0 | U11: 0 | V11: 0 | W11: Nihil | X11: 124 | Y11: 2 | Z11: Ruas jalan di Jl. Raya Tajem sebenarnya memiliki lampu di sisi timurnya, kami melakukan survei ruas jalan di sisi barat jalan. Lampu jalan di sisi timur tidak memiliki cukup penerangan hingga ruas jalan barat | AA11: 4 | AB11: 1.13 | AC11: =IF($K11="","",IF($K11="Ada",1,IF($K11="Sebagian",0.5,0))) | AD11: =IF($K11="","",IF($K11="Tidak ada",0,IF($L11="","",MIN($L11/Panduan_W6!$B$9,1)))) | AE11: =IF($K11="","",IF($K11="Tidak ada",0,IF(OR($N11="",$H11=""),"",MAX(0,1-$N11/$H11)))) | AF11: =IF(OR($K11="",$K11="Tidak ada"),"",IF(OR($P11="",$H11=""),"",EXP(-$P11/$H11*100/Panduan_W6!$B$10))) | AG11: =IF($Q11="","",IF($Q11="Tidak",1,0)) | AH11: =IF(ISNUMBER(AC11),Panduan_W6!$B$4,0)+IF(ISNUMBER(AD11),Panduan_W6!$B$5,0)+IF(ISNUMBER(AE11),Panduan_W6!$B$6,0)+IF(ISNUMBER(AF11),Panduan_W6!$B$7,0)+IF(ISNUMBER(AG11),Panduan_W6!$B$8,0) | AI11: =IF(LEFT(AJ11,7)<>"Lengkap","",IF(AJ11="Lengkap (gang)",AG11,(IF(ISNUMBER(AC11),Panduan_W6!$B$4*AC11,0)+IF(ISNUMBER(AD11),Panduan_W6!$B$5*AD11,0)+IF(ISNUMBER(AE11),Panduan_W6!$B$6*AE11,0)+IF(ISNUMBER(AF11),Panduan_W6!$B$7*AF11,0)+IF(ISNUMBER(AG11),Panduan_W6!$B$8*AG11,0))/AH11)) | AJ11: =IF(AND(Panduan_W6!$B$11="Ya",$I11="Gang",$J11="Sepi"),IF(ISNUMBER(AG11),"Lengkap (gang)","Belum lengkap"),IF(AND(ISNUMBER(AC11),ISNUMBER(AD11),ISNUMBER(AE11),ISNUMBER(AG11),OR(ISNUMBER(AF11),$K11="Tidak ada")),"Lengkap","Belum lengkap"))
A12: RUAS-011 | B12: Day 1 | C12: KWS-11 | D12: Theo | E12: 2026-08-16 | G12: JI. Pandega Maharsi | H12: 142.51 | I12: Jalan kecil | J12: Sepi | K12: Tidak ada | L12: 0 | M12: 4.2 | N12: 0 | O12: tidak ada | P12: 0 | Q12: Tidak | R12: 0 | S12: 0 | T12: 6 | U12: 0 | V12: 22.5 | W12: 25 sampai 50 persen | X12: 245 | Y12: 1 | Z12: jalan udah bagus ada banyak polisi tidur yang sudah retak | AA12: 1.5 | AB12: 0.58 | AC12: =IF($K12="","",IF($K12="Ada",1,IF($K12="Sebagian",0.5,0))) | AD12: =IF($K12="","",IF($K12="Tidak ada",0,IF($L12="","",MIN($L12/Panduan_W6!$B$9,1)))) | AE12: =IF($K12="","",IF($K12="Tidak ada",0,IF(OR($N12="",$H12=""),"",MAX(0,1-$N12/$H12)))) | AF12: =IF(OR($K12="",$K12="Tidak ada"),"",IF(OR($P12="",$H12=""),"",EXP(-$P12/$H12*100/Panduan_W6!$B$10))) | AG12: =IF($Q12="","",IF($Q12="Tidak",1,0)) | AH12: =IF(ISNUMBER(AC12),Panduan_W6!$B$4,0)+IF(ISNUMBER(AD12),Panduan_W6!$B$5,0)+IF(ISNUMBER(AE12),Panduan_W6!$B$6,0)+IF(ISNUMBER(AF12),Panduan_W6!$B$7,0)+IF(ISNUMBER(AG12),Panduan_W6!$B$8,0) | AI12: =IF(LEFT(AJ12,7)<>"Lengkap","",IF(AJ12="Lengkap (gang)",AG12,(IF(ISNUMBER(AC12),Panduan_W6!$B$4*AC12,0)+IF(ISNUMBER(AD12),Panduan_W6!$B$5*AD12,0)+IF(ISNUMBER(AE12),Panduan_W6!$B$6*AE12,0)+IF(ISNUMBER(AF12),Panduan_W6!$B$7*AF12,0)+IF(ISNUMBER(AG12),Panduan_W6!$B$8*AG12,0))/AH12)) | AJ12: =IF(AND(Panduan_W6!$B$11="Ya",$I12="Gang",$J12="Sepi"),IF(ISNUMBER(AG12),"Lengkap (gang)","Belum lengkap"),IF(AND(ISNUMBER(AC12),ISNUMBER(AD12),ISNUMBER(AE12),ISNUMBER(AG12),OR(ISNUMBER(AF12),$K12="Tidak ada")),"Lengkap","Belum lengkap"))
A13: RUAS-012 | B13: Day 1 | C13: KWS-04 | D13: Devon | E13: 2026-08-16 | F13: 16:07 | G13: Jl. Raya Tajem | H13: 130 | I13: Jalan raya | J13: Ramai | K13: Ada | L13: 1 | M13: 10 | N13: 3 | O13: mobil parkir | P13: 1 | Q13: Ya | R13: 0 | S13: 0 | T13: 0 | U13: 0 | V13: 0 | W13: Nihil | X13: 120 | Y13: 1 | AA13: 4 | AB13: 1.08 | AC13: =IF($K13="","",IF($K13="Ada",1,IF($K13="Sebagian",0.5,0))) | AD13: =IF($K13="","",IF($K13="Tidak ada",0,IF($L13="","",MIN($L13/Panduan_W6!$B$9,1)))) | AE13: =IF($K13="","",IF($K13="Tidak ada",0,IF(OR($N13="",$H13=""),"",MAX(0,1-$N13/$H13)))) | AF13: =IF(OR($K13="",$K13="Tidak ada"),"",IF(OR($P13="",$H13=""),"",EXP(-$P13/$H13*100/Panduan_W6!$B$10))) | AG13: =IF($Q13="","",IF($Q13="Tidak",1,0)) | AH13: =IF(ISNUMBER(AC13),Panduan_W6!$B$4,0)+IF(ISNUMBER(AD13),Panduan_W6!$B$5,0)+IF(ISNUMBER(AE13),Panduan_W6!$B$6,0)+IF(ISNUMBER(AF13),Panduan_W6!$B$7,0)+IF(ISNUMBER(AG13),Panduan_W6!$B$8,0) | AI13: =IF(LEFT(AJ13,7)<>"Lengkap","",IF(AJ13="Lengkap (gang)",AG13,(IF(ISNUMBER(AC13),Panduan_W6!$B$4*AC13,0)+IF(ISNUMBER(AD13),Panduan_W6!$B$5*AD13,0)+IF(ISNUMBER(AE13),Panduan_W6!$B$6*AE13,0)+IF(ISNUMBER(AF13),Panduan_W6!$B$7*AF13,0)+IF(ISNUMBER(AG13),Panduan_W6!$B$8*AG13,0))/AH13)) | AJ13: =IF(AND(Panduan_W6!$B$11="Ya",$I13="Gang",$J13="Sepi"),IF(ISNUMBER(AG13),"Lengkap (gang)","Belum lengkap"),IF(AND(ISNUMBER(AC13),ISNUMBER(AD13),ISNUMBER(AE13),ISNUMBER(AG13),OR(ISNUMBER(AF13),$K13="Tidak ada")),"Lengkap","Belum lengkap"))
A14: RUAS-013 | B14: Day 1 | C14: KWS-11 | D14: Andalan | E14: 2026-08-16 | F14: 16:09 | G14: Jl. Kaliurang Km 6 | H14: 220 | I14: Jalan raya | J14: Ramai | K14: Tidak ada | L14: 0 | M14: 9 | N14: 0 | O14: tidak ada | P14: 0 | Q14: Tidak | R14: 0 | S14: 0 | T14: 4 | U14: 0 | V14: 110 | W14: Nihil | X14: 200 | Y14: 2 | Z14: Jalan paling rame sejauh ini. Nyebrang sangat sulit. Berdebu krn byk kendaraanBanyak sekali usaha di kedua sisi jalan, seperti kuliner, kesehatan, bengkel, dsb. | AA14: 4 | AB14: 1.1 | AC14: =IF($K14="","",IF($K14="Ada",1,IF($K14="Sebagian",0.5,0))) | AD14: =IF($K14="","",IF($K14="Tidak ada",0,IF($L14="","",MIN($L14/Panduan_W6!$B$9,1)))) | AE14: =IF($K14="","",IF($K14="Tidak ada",0,IF(OR($N14="",$H14=""),"",MAX(0,1-$N14/$H14)))) | AF14: =IF(OR($K14="",$K14="Tidak ada"),"",IF(OR($P14="",$H14=""),"",EXP(-$P14/$H14*100/Panduan_W6!$B$10))) | AG14: =IF($Q14="","",IF($Q14="Tidak",1,0)) | AH14: =IF(ISNUMBER(AC14),Panduan_W6!$B$4,0)+IF(ISNUMBER(AD14),Panduan_W6!$B$5,0)+IF(ISNUMBER(AE14),Panduan_W6!$B$6,0)+IF(ISNUMBER(AF14),Panduan_W6!$B$7,0)+IF(ISNUMBER(AG14),Panduan_W6!$B$8,0) | AI14: =IF(LEFT(AJ14,7)<>"Lengkap","",IF(AJ14="Lengkap (gang)",AG14,(IF(ISNUMBER(AC14),Panduan_W6!$B$4*AC14,0)+IF(ISNUMBER(AD14),Panduan_W6!$B$5*AD14,0)+IF(ISNUMBER(AE14),Panduan_W6!$B$6*AE14,0)+IF(ISNUMBER(AF14),Panduan_W6!$B$7*AF14,0)+IF(ISNUMBER(AG14),Panduan_W6!$B$8*AG14,0))/AH14)) | AJ14: =IF(AND(Panduan_W6!$B$11="Ya",$I14="Gang",$J14="Sepi"),IF(ISNUMBER(AG14),"Lengkap (gang)","Belum lengkap"),IF(AND(ISNUMBER(AC14),ISNUMBER(AD14),ISNUMBER(AE14),ISNUMBER(AG14),OR(ISNUMBER(AF14),$K14="Tidak ada")),"Lengkap","Belum lengkap"))
A15: RUAS-014 | B15: Day 1 | C15: KWS-04 | D15: Devon | E15: 2026-08-16 | F15: 16:23 | G15: Jl. Raya Tajem | H15: 230 | I15: Jalan raya | J15: Ramai | K15: Ada | L15: 1 | M15: 10 | N15: 3 | O15: mobil parkir | P15: 0 | Q15: Ya | R15: 0 | S15: 0 | T15: 1 | U15: 0 | W15: Di bawah 25 persen | X15: 203 | Y15: 1 | Z15: Akhirnya di ruas jalan raya tajem, terdapat penerangan jalan. Lampu penerangan kecil dibawah spanduk toko bangunan. | AA15: 4 | AB15: 1.13 | AC15: =IF($K15="","",IF($K15="Ada",1,IF($K15="Sebagian",0.5,0))) | AD15: =IF($K15="","",IF($K15="Tidak ada",0,IF($L15="","",MIN($L15/Panduan_W6!$B$9,1)))) | AE15: =IF($K15="","",IF($K15="Tidak ada",0,IF(OR($N15="",$H15=""),"",MAX(0,1-$N15/$H15)))) | AF15: =IF(OR($K15="",$K15="Tidak ada"),"",IF(OR($P15="",$H15=""),"",EXP(-$P15/$H15*100/Panduan_W6!$B$10))) | AG15: =IF($Q15="","",IF($Q15="Tidak",1,0)) | AH15: =IF(ISNUMBER(AC15),Panduan_W6!$B$4,0)+IF(ISNUMBER(AD15),Panduan_W6!$B$5,0)+IF(ISNUMBER(AE15),Panduan_W6!$B$6,0)+IF(ISNUMBER(AF15),Panduan_W6!$B$7,0)+IF(ISNUMBER(AG15),Panduan_W6!$B$8,0) | AI15: =IF(LEFT(AJ15,7)<>"Lengkap","",IF(AJ15="Lengkap (gang)",AG15,(IF(ISNUMBER(AC15),Panduan_W6!$B$4*AC15,0)+IF(ISNUMBER(AD15),Panduan_W6!$B$5*AD15,0)+IF(ISNUMBER(AE15),Panduan_W6!$B$6*AE15,0)+IF(ISNUMBER(AF15),Panduan_W6!$B$7*AF15,0)+IF(ISNUMBER(AG15),Panduan_W6!$B$8*AG15,0))/AH15)) | AJ15: =IF(AND(Panduan_W6!$B$11="Ya",$I15="Gang",$J15="Sepi"),IF(ISNUMBER(AG15),"Lengkap (gang)","Belum lengkap"),IF(AND(ISNUMBER(AC15),ISNUMBER(AD15),ISNUMBER(AE15),ISNUMBER(AG15),OR(ISNUMBER(AF15),$K15="Tidak ada")),"Lengkap","Belum lengkap"))
A16: RUAS-015 | B16: Day 1 | C16: KWS-04 | D16: Delon | E16: 2026-08-16 | F16: 16:32 | G16: Jl. Stadion | H16: 235 | I16: Jalan raya | J16: Sedang | K16: Ada | L16: 1.8 | M16: 12 | N16: 40 | O16: mobil parkir, papan spanduk | P16: 12 | Q16: Ya | R16: 1 | S16: 0 | T16: 5 | U16: 0 | W16: Di bawah 25 persen | X16: 225 | Y16: 2 | Z16: ada pedagang durian di ruas jalan yang memarkirkan mobil di jalan raya, ada juga dupa tertancap di samping ruas jalan | AA16: 4 | AB16: 1.04 | AC16: =IF($K16="","",IF($K16="Ada",1,IF($K16="Sebagian",0.5,0))) | AD16: =IF($K16="","",IF($K16="Tidak ada",0,IF($L16="","",MIN($L16/Panduan_W6!$B$9,1)))) | AE16: =IF($K16="","",IF($K16="Tidak ada",0,IF(OR($N16="",$H16=""),"",MAX(0,1-$N16/$H16)))) | AF16: =IF(OR($K16="",$K16="Tidak ada"),"",IF(OR($P16="",$H16=""),"",EXP(-$P16/$H16*100/Panduan_W6!$B$10))) | AG16: =IF($Q16="","",IF($Q16="Tidak",1,0)) | AH16: =IF(ISNUMBER(AC16),Panduan_W6!$B$4,0)+IF(ISNUMBER(AD16),Panduan_W6!$B$5,0)+IF(ISNUMBER(AE16),Panduan_W6!$B$6,0)+IF(ISNUMBER(AF16),Panduan_W6!$B$7,0)+IF(ISNUMBER(AG16),Panduan_W6!$B$8,0) | AI16: =IF(LEFT(AJ16,7)<>"Lengkap","",IF(AJ16="Lengkap (gang)",AG16,(IF(ISNUMBER(AC16),Panduan_W6!$B$4*AC16,0)+IF(ISNUMBER(AD16),Panduan_W6!$B$5*AD16,0)+IF(ISNUMBER(AE16),Panduan_W6!$B$6*AE16,0)+IF(ISNUMBER(AF16),Panduan_W6!$B$7*AF16,0)+IF(ISNUMBER(AG16),Panduan_W6!$B$8*AG16,0))/AH16)) | AJ16: =IF(AND(Panduan_W6!$B$11="Ya",$I16="Gang",$J16="Sepi"),IF(ISNUMBER(AG16),"Lengkap (gang)","Belum lengkap"),IF(AND(ISNUMBER(AC16),ISNUMBER(AD16),ISNUMBER(AE16),ISNUMBER(AG16),OR(ISNUMBER(AF16),$K16="Tidak ada")),"Lengkap","Belum lengkap"))
A17: RUAS-016 | B17: Day 1 | C17: KWS-11 | D17: Andalan | E17: 2026-08-16 | F17: 16:31 | G17: Jl. Kaliurang Km 6 | H17: 250 | I17: Jalan raya | J17: Ramai | K17: Sebagian | L17: 1.4 | M17: 12 | N17: 115 | O17: material bangunan | P17: 2 | Q17: Ya | R17: 0 | S17: 0 | T17: 4 | U17: 2 | V17: 45 | W17: Di bawah 25 persen | X17: 200 | Y17: 1 | Z17: Toko bangunan pasirnya menghalang jalan. Kondisi keseluruhan masih sama dengan jalan kaliurang km 6 tadi | AA17: 4 | AB17: 1.25 | AC17: =IF($K17="","",IF($K17="Ada",1,IF($K17="Sebagian",0.5,0))) | AD17: =IF($K17="","",IF($K17="Tidak ada",0,IF($L17="","",MIN($L17/Panduan_W6!$B$9,1)))) | AE17: =IF($K17="","",IF($K17="Tidak ada",0,IF(OR($N17="",$H17=""),"",MAX(0,1-$N17/$H17)))) | AF17: =IF(OR($K17="",$K17="Tidak ada"),"",IF(OR($P17="",$H17=""),"",EXP(-$P17/$H17*100/Panduan_W6!$B$10))) | AG17: =IF($Q17="","",IF($Q17="Tidak",1,0)) | AH17: =IF(ISNUMBER(AC17),Panduan_W6!$B$4,0)+IF(ISNUMBER(AD17),Panduan_W6!$B$5,0)+IF(ISNUMBER(AE17),Panduan_W6!$B$6,0)+IF(ISNUMBER(AF17),Panduan_W6!$B$7,0)+IF(ISNUMBER(AG17),Panduan_W6!$B$8,0) | AI17: =IF(LEFT(AJ17,7)<>"Lengkap","",IF(AJ17="Lengkap (gang)",AG17,(IF(ISNUMBER(AC17),Panduan_W6!$B$4*AC17,0)+IF(ISNUMBER(AD17),Panduan_W6!$B$5*AD17,0)+IF(ISNUMBER(AE17),Panduan_W6!$B$6*AE17,0)+IF(ISNUMBER(AF17),Panduan_W6!$B$7*AF17,0)+IF(ISNUMBER(AG17),Panduan_W6!$B$8*AG17,0))/AH17)) | AJ17: =IF(AND(Panduan_W6!$B$11="Ya",$I17="Gang",$J17="Sepi"),IF(ISNUMBER(AG17),"Lengkap (gang)","Belum lengkap"),IF(AND(ISNUMBER(AC17),ISNUMBER(AD17),ISNUMBER(AE17),ISNUMBER(AG17),OR(ISNUMBER(AF17),$K17="Tidak ada")),"Lengkap","Belum lengkap"))
A18: RUAS-017 | B18: Day 1 | C18: KWS-11 | D18: Theo | E18: 2026-08-16 | F18: 16:42 | G18: Gg. Pandega Rini | H18: 93.02 | I18: Jalan kecil | J18: Sepi | K18: Tidak ada | L18: 0 | M18: 4.2 | N18: 0 | O18: mobil parkir | P18: 0 | Q18: Ya | R18: 0 | S18: 0 | T18: 3 | U18: 0 | V18: 25.29 | W18: 25 sampai 50 persen | X18: 135 | Z18: ruasnya bagus namun beberapa polisi tidur agak rusak | AA18: 1 | AB18: 0.69 | AC18: =IF($K18="","",IF($K18="Ada",1,IF($K18="Sebagian",0.5,0))) | AD18: =IF($K18="","",IF($K18="Tidak ada",0,IF($L18="","",MIN($L18/Panduan_W6!$B$9,1)))) | AE18: =IF($K18="","",IF($K18="Tidak ada",0,IF(OR($N18="",$H18=""),"",MAX(0,1-$N18/$H18)))) | AF18: =IF(OR($K18="",$K18="Tidak ada"),"",IF(OR($P18="",$H18=""),"",EXP(-$P18/$H18*100/Panduan_W6!$B$10))) | AG18: =IF($Q18="","",IF($Q18="Tidak",1,0)) | AH18: =IF(ISNUMBER(AC18),Panduan_W6!$B$4,0)+IF(ISNUMBER(AD18),Panduan_W6!$B$5,0)+IF(ISNUMBER(AE18),Panduan_W6!$B$6,0)+IF(ISNUMBER(AF18),Panduan_W6!$B$7,0)+IF(ISNUMBER(AG18),Panduan_W6!$B$8,0) | AI18: =IF(LEFT(AJ18,7)<>"Lengkap","",IF(AJ18="Lengkap (gang)",AG18,(IF(ISNUMBER(AC18),Panduan_W6!$B$4*AC18,0)+IF(ISNUMBER(AD18),Panduan_W6!$B$5*AD18,0)+IF(ISNUMBER(AE18),Panduan_W6!$B$6*AE18,0)+IF(ISNUMBER(AF18),Panduan_W6!$B$7*AF18,0)+IF(ISNUMBER(AG18),Panduan_W6!$B$8*AG18,0))/AH18)) | AJ18: =IF(AND(Panduan_W6!$B$11="Ya",$I18="Gang",$J18="Sepi"),IF(ISNUMBER(AG18),"Lengkap (gang)","Belum lengkap"),IF(AND(ISNUMBER(AC18),ISNUMBER(AD18),ISNUMBER(AE18),ISNUMBER(AG18),OR(ISNUMBER(AF18),$K18="Tidak ada")),"Lengkap","Belum lengkap"))
A19: RUAS-018 | B19: Day 1 | C19: KWS-04 | D19: Delon | E19: 2026-08-16 | F19: 16:51 | G19: Jl. Stadion | H19: 250 | I19: Jalan raya | J19: Sedang | K19: Ada | L19: 1.2 | M19: 12 | N19: 2 | O19: lubang drainase yang terbuka | P19: 15 | Q19: Tidak | R19: 0 | S19: 0 | T19: 7 | U19: 0 | V19: 30 | W19: Nihil | X19: 255 | Y19: 1 | Z19: cukup ramah pejalan kaki, penerangan bagus, tapi keteduhan nihil banyak paving lepas serta ada lubang drainase terbuka | AA19: 4 | AB19: 0.98 | AC19: =IF($K19="","",IF($K19="Ada",1,IF($K19="Sebagian",0.5,0))) | AD19: =IF($K19="","",IF($K19="Tidak ada",0,IF($L19="","",MIN($L19/Panduan_W6!$B$9,1)))) | AE19: =IF($K19="","",IF($K19="Tidak ada",0,IF(OR($N19="",$H19=""),"",MAX(0,1-$N19/$H19)))) | AF19: =IF(OR($K19="",$K19="Tidak ada"),"",IF(OR($P19="",$H19=""),"",EXP(-$P19/$H19*100/Panduan_W6!$B$10))) | AG19: =IF($Q19="","",IF($Q19="Tidak",1,0)) | AH19: =IF(ISNUMBER(AC19),Panduan_W6!$B$4,0)+IF(ISNUMBER(AD19),Panduan_W6!$B$5,0)+IF(ISNUMBER(AE19),Panduan_W6!$B$6,0)+IF(ISNUMBER(AF19),Panduan_W6!$B$7,0)+IF(ISNUMBER(AG19),Panduan_W6!$B$8,0) | AI19: =IF(LEFT(AJ19,7)<>"Lengkap","",IF(AJ19="Lengkap (gang)",AG19,(IF(ISNUMBER(AC19),Panduan_W6!$B$4*AC19,0)+IF(ISNUMBER(AD19),Panduan_W6!$B$5*AD19,0)+IF(ISNUMBER(AE19),Panduan_W6!$B$6*AE19,0)+IF(ISNUMBER(AF19),Panduan_W6!$B$7*AF19,0)+IF(ISNUMBER(AG19),Panduan_W6!$B$8*AG19,0))/AH19)) | AJ19: =IF(AND(Panduan_W6!$B$11="Ya",$I19="Gang",$J19="Sepi"),IF(ISNUMBER(AG19),"Lengkap (gang)","Belum lengkap"),IF(AND(ISNUMBER(AC19),ISNUMBER(AD19),ISNUMBER(AE19),ISNUMBER(AG19),OR(ISNUMBER(AF19),$K19="Tidak ada")),"Lengkap","Belum lengkap"))
A20: RUAS-019 | B20: Day 1 | C20: KWS-11 | D20: Theo | E20: 2026-08-16 | F20: 16:58 | G20: Jl Ringroad Utara km 15 | H20: 132.9 | I20: Jalan raya | J20: Sedang | K20: Ada | L20: 1.15 | M20: 5.25 | N20: 73.3 | O20: akar pohon dan tiang listrik | P20: 7 | Q20: Tidak | R20: 0 | S20: 0 | T20: 3 | U20: 0 | V20: 19.37 | W20: Di bawah 25 persen | X20: 141 | Y20: 1 | Z20: cukup untuk jalan saja namun tidak baik untuk orang yang punya kekurangan dalam berjalan | AA20: 2 | AB20: 0.94 | AC20: =IF($K20="","",IF($K20="Ada",1,IF($K20="Sebagian",0.5,0))) | AD20: =IF($K20="","",IF($K20="Tidak ada",0,IF($L20="","",MIN($L20/Panduan_W6!$B$9,1)))) | AE20: =IF($K20="","",IF($K20="Tidak ada",0,IF(OR($N20="",$H20=""),"",MAX(0,1-$N20/$H20)))) | AF20: =IF(OR($K20="",$K20="Tidak ada"),"",IF(OR($P20="",$H20=""),"",EXP(-$P20/$H20*100/Panduan_W6!$B$10))) | AG20: =IF($Q20="","",IF($Q20="Tidak",1,0)) | AH20: =IF(ISNUMBER(AC20),Panduan_W6!$B$4,0)+IF(ISNUMBER(AD20),Panduan_W6!$B$5,0)+IF(ISNUMBER(AE20),Panduan_W6!$B$6,0)+IF(ISNUMBER(AF20),Panduan_W6!$B$7,0)+IF(ISNUMBER(AG20),Panduan_W6!$B$8,0) | AI20: =IF(LEFT(AJ20,7)<>"Lengkap","",IF(AJ20="Lengkap (gang)",AG20,(IF(ISNUMBER(AC20),Panduan_W6!$B$4*AC20,0)+IF(ISNUMBER(AD20),Panduan_W6!$B$5*AD20,0)+IF(ISNUMBER(AE20),Panduan_W6!$B$6*AE20,0)+IF(ISNUMBER(AF20),Panduan_W6!$B$7*AF20,0)+IF(ISNUMBER(AG20),Panduan_W6!$B$8*AG20,0))/AH20)) | AJ20: =IF(AND(Panduan_W6!$B$11="Ya",$I20="Gang",$J20="Sepi"),IF(ISNUMBER(AG20),"Lengkap (gang)","Belum lengkap"),IF(AND(ISNUMBER(AC20),ISNUMBER(AD20),ISNUMBER(AE20),ISNUMBER(AG20),OR(ISNUMBER(AF20),$K20="Tidak ada")),"Lengkap","Belum lengkap"))
A21: RUAS-020 | B21: Day 1 | C21: KWS-04 | D21: Devon | E21: 2026-08-16 | F21: 17:02 | G21: Jl. Stadion | H21: 160 | I21: Jalan raya | J21: Sedang | K21: Ada | L21: 1.2 | M21: 12 | N21: 0.5 | O21: jalan, paving lepas | P21: 13 | Q21: Ya | R21: 0 | S21: 0 | T21: 5 | U21: 0 | V21: 20 | W21: Nihil | X21: 158 | Y21: 1 | Z21: trotoar banyak yang rusak, ada bagian yang tidak dapat dilewati karena rusak | AA21: 4 | AB21: 1.01 | AC21: =IF($K21="","",IF($K21="Ada",1,IF($K21="Sebagian",0.5,0))) | AD21: =IF($K21="","",IF($K21="Tidak ada",0,IF($L21="","",MIN($L21/Panduan_W6!$B$9,1)))) | AE21: =IF($K21="","",IF($K21="Tidak ada",0,IF(OR($N21="",$H21=""),"",MAX(0,1-$N21/$H21)))) | AF21: =IF(OR($K21="",$K21="Tidak ada"),"",IF(OR($P21="",$H21=""),"",EXP(-$P21/$H21*100/Panduan_W6!$B$10))) | AG21: =IF($Q21="","",IF($Q21="Tidak",1,0)) | AH21: =IF(ISNUMBER(AC21),Panduan_W6!$B$4,0)+IF(ISNUMBER(AD21),Panduan_W6!$B$5,0)+IF(ISNUMBER(AE21),Panduan_W6!$B$6,0)+IF(ISNUMBER(AF21),Panduan_W6!$B$7,0)+IF(ISNUMBER(AG21),Panduan_W6!$B$8,0) | AI21: =IF(LEFT(AJ21,7)<>"Lengkap","",IF(AJ21="Lengkap (gang)",AG21,(IF(ISNUMBER(AC21),Panduan_W6!$B$4*AC21,0)+IF(ISNUMBER(AD21),Panduan_W6!$B$5*AD21,0)+IF(ISNUMBER(AE21),Panduan_W6!$B$6*AE21,0)+IF(ISNUMBER(AF21),Panduan_W6!$B$7*AF21,0)+IF(ISNUMBER(AG21),Panduan_W6!$B$8*AG21,0))/AH21)) | AJ21: =IF(AND(Panduan_W6!$B$11="Ya",$I21="Gang",$J21="Sepi"),IF(ISNUMBER(AG21),"Lengkap (gang)","Belum lengkap"),IF(AND(ISNUMBER(AC21),ISNUMBER(AD21),ISNUMBER(AE21),ISNUMBER(AG21),OR(ISNUMBER(AF21),$K21="Tidak ada")),"Lengkap","Belum lengkap"))
A22: RUAS-021 | B22: Day 1 | C22: KWS-04 | D22: Delon | E22: 2026-08-16 | F22: 17:59 | G22: Jl. Raya Tajem | H22: 110 | I22: Jalan raya | J22: Ramai | K22: Tidak ada | L22: 0 | M22: 10 | N22: 0 | O22: mobil dan motor parkir | P22: 0 | Q22: Ya | R22: 0 | S22: 0 | T22: 0 | U22: 0 | V22: 0 | W22: Nihil | X22: 195 | Z22: tidak ada trotoar, area pejalan kaki banyak tertutup kendaraan, tidan ada lampu di sisi timur, tidak ada pohon | AA22: 4 | AB22: 0.56 | AC22: =IF($K22="","",IF($K22="Ada",1,IF($K22="Sebagian",0.5,0))) | AD22: =IF($K22="","",IF($K22="Tidak ada",0,IF($L22="","",MIN($L22/Panduan_W6!$B$9,1)))) | AE22: =IF($K22="","",IF($K22="Tidak ada",0,IF(OR($N22="",$H22=""),"",MAX(0,1-$N22/$H22)))) | AF22: =IF(OR($K22="",$K22="Tidak ada"),"",IF(OR($P22="",$H22=""),"",EXP(-$P22/$H22*100/Panduan_W6!$B$10))) | AG22: =IF($Q22="","",IF($Q22="Tidak",1,0)) | AH22: =IF(ISNUMBER(AC22),Panduan_W6!$B$4,0)+IF(ISNUMBER(AD22),Panduan_W6!$B$5,0)+IF(ISNUMBER(AE22),Panduan_W6!$B$6,0)+IF(ISNUMBER(AF22),Panduan_W6!$B$7,0)+IF(ISNUMBER(AG22),Panduan_W6!$B$8,0) | AI22: =IF(LEFT(AJ22,7)<>"Lengkap","",IF(AJ22="Lengkap (gang)",AG22,(IF(ISNUMBER(AC22),Panduan_W6!$B$4*AC22,0)+IF(ISNUMBER(AD22),Panduan_W6!$B$5*AD22,0)+IF(ISNUMBER(AE22),Panduan_W6!$B$6*AE22,0)+IF(ISNUMBER(AF22),Panduan_W6!$B$7*AF22,0)+IF(ISNUMBER(AG22),Panduan_W6!$B$8*AG22,0))/AH22)) | AJ22: =IF(AND(Panduan_W6!$B$11="Ya",$I22="Gang",$J22="Sepi"),IF(ISNUMBER(AG22),"Lengkap (gang)","Belum lengkap"),IF(AND(ISNUMBER(AC22),ISNUMBER(AD22),ISNUMBER(AE22),ISNUMBER(AG22),OR(ISNUMBER(AF22),$K22="Tidak ada")),"Lengkap","Belum lengkap"))
A23: RUAS-022 | B23: Day 2 | C23: KWS-07 | D23: Andalan | E23: 2026-08-17 | F23: 08:33 | G23: Gg. Pucung Baru 1, Depok | H23: 110 | I23: Gang | J23: Sepi | K23: Tidak ada | L23: 0 | M23: 4 | N23: 0 | O23: tidak ada | P23: 0 | Q23: Ya | R23: 0 | S23: 0 | T23: 3 | U23: 0 | V23: 35 | W23: 25 sampai 50 persen | X23: 74 | Y23: 1 | Z23: cukup rindang, gang nya ada kos mewah, tinggi maks kendaraan sekitar 2.2 m | AA23: 1 | AB23: 1.49 | AC23: =IF($K23="","",IF($K23="Ada",1,IF($K23="Sebagian",0.5,0))) | AD23: =IF($K23="","",IF($K23="Tidak ada",0,IF($L23="","",MIN($L23/Panduan_W6!$B$9,1)))) | AE23: =IF($K23="","",IF($K23="Tidak ada",0,IF(OR($N23="",$H23=""),"",MAX(0,1-$N23/$H23)))) | AF23: =IF(OR($K23="",$K23="Tidak ada"),"",IF(OR($P23="",$H23=""),"",EXP(-$P23/$H23*100/Panduan_W6!$B$10))) | AG23: =IF($Q23="","",IF($Q23="Tidak",1,0)) | AH23: =IF(ISNUMBER(AC23),Panduan_W6!$B$4,0)+IF(ISNUMBER(AD23),Panduan_W6!$B$5,0)+IF(ISNUMBER(AE23),Panduan_W6!$B$6,0)+IF(ISNUMBER(AF23),Panduan_W6!$B$7,0)+IF(ISNUMBER(AG23),Panduan_W6!$B$8,0) | AI23: =IF(LEFT(AJ23,7)<>"Lengkap","",IF(AJ23="Lengkap (gang)",AG23,(IF(ISNUMBER(AC23),Panduan_W6!$B$4*AC23,0)+IF(ISNUMBER(AD23),Panduan_W6!$B$5*AD23,0)+IF(ISNUMBER(AE23),Panduan_W6!$B$6*AE23,0)+IF(ISNUMBER(AF23),Panduan_W6!$B$7*AF23,0)+IF(ISNUMBER(AG23),Panduan_W6!$B$8*AG23,0))/AH23)) | AJ23: =IF(AND(Panduan_W6!$B$11="Ya",$I23="Gang",$J23="Sepi"),IF(ISNUMBER(AG23),"Lengkap (gang)","Belum lengkap"),IF(AND(ISNUMBER(AC23),ISNUMBER(AD23),ISNUMBER(AE23),ISNUMBER(AG23),OR(ISNUMBER(AF23),$K23="Tidak ada")),"Lengkap","Belum lengkap"))
A24: RUAS-023 | B24: Day 2 | C24: KWS-07 | D24: Theo | E24: 2026-08-17 | F24: 08:46 | G24: Jl. Ringroad Utara | H24: 180.68 | I24: Jalan raya | J24: Ramai | K24: Sebagian | L24: 1.05 | M24: 10.5 | N24: 104 | O24: tidak ada | P24: 0 | Q24: Ya | R24: 0 | S24: 0 | T24: 3 | U24: 0 | V24: 84 | W24: Di bawah 25 persen | X24: 185 | Y24: 1 | Z24: jalanan cukup baik namun trotoar hany untuk masuk ke rumah sakit saja tidak untuk spenih jalan | AA24: 3 | AB24: 0.98 | AC24: =IF($K24="","",IF($K24="Ada",1,IF($K24="Sebagian",0.5,0))) | AD24: =IF($K24="","",IF($K24="Tidak ada",0,IF($L24="","",MIN($L24/Panduan_W6!$B$9,1)))) | AE24: =IF($K24="","",IF($K24="Tidak ada",0,IF(OR($N24="",$H24=""),"",MAX(0,1-$N24/$H24)))) | AF24: =IF(OR($K24="",$K24="Tidak ada"),"",IF(OR($P24="",$H24=""),"",EXP(-$P24/$H24*100/Panduan_W6!$B$10))) | AG24: =IF($Q24="","",IF($Q24="Tidak",1,0)) | AH24: =IF(ISNUMBER(AC24),Panduan_W6!$B$4,0)+IF(ISNUMBER(AD24),Panduan_W6!$B$5,0)+IF(ISNUMBER(AE24),Panduan_W6!$B$6,0)+IF(ISNUMBER(AF24),Panduan_W6!$B$7,0)+IF(ISNUMBER(AG24),Panduan_W6!$B$8,0) | AI24: =IF(LEFT(AJ24,7)<>"Lengkap","",IF(AJ24="Lengkap (gang)",AG24,(IF(ISNUMBER(AC24),Panduan_W6!$B$4*AC24,0)+IF(ISNUMBER(AD24),Panduan_W6!$B$5*AD24,0)+IF(ISNUMBER(AE24),Panduan_W6!$B$6*AE24,0)+IF(ISNUMBER(AF24),Panduan_W6!$B$7*AF24,0)+IF(ISNUMBER(AG24),Panduan_W6!$B$8*AG24,0))/AH24)) | AJ24: =IF(AND(Panduan_W6!$B$11="Ya",$I24="Gang",$J24="Sepi"),IF(ISNUMBER(AG24),"Lengkap (gang)","Belum lengkap"),IF(AND(ISNUMBER(AC24),ISNUMBER(AD24),ISNUMBER(AE24),ISNUMBER(AG24),OR(ISNUMBER(AF24),$K24="Tidak ada")),"Lengkap","Belum lengkap"))
A25: RUAS-024 | B25: Day 2 | C25: KWS-07 | D25: Andalan | E25: 2026-08-17 | F25: 09:00 | G25: Gg. Pucung Baru 1, Depok | H25: 140 | I25: Gang | J25: Sepi | K25: Tidak ada | L25: 0 | M25: 4 | N25: 0 | O25: tidak ada | P25: 1 | Q25: Ya | R25: 0 | S25: 0 | T25: 3 | U25: 0 | V25: 90 | W25: 25 sampai 50 persen | X25: 96 | Y25: 3 | Z25: masih di gang yang sama (masuk lebih dalam), ternyata banyak kos eksklusif (ada 4) seperti kos mewah gitu. ada asrama dan tanah dijual juga. hawanya juga rindang krn byk penghijauan | AA25: 1 | AB25: 1.46 | AC25: =IF($K25="","",IF($K25="Ada",1,IF($K25="Sebagian",0.5,0))) | AD25: =IF($K25="","",IF($K25="Tidak ada",0,IF($L25="","",MIN($L25/Panduan_W6!$B$9,1)))) | AE25: =IF($K25="","",IF($K25="Tidak ada",0,IF(OR($N25="",$H25=""),"",MAX(0,1-$N25/$H25)))) | AF25: =IF(OR($K25="",$K25="Tidak ada"),"",IF(OR($P25="",$H25=""),"",EXP(-$P25/$H25*100/Panduan_W6!$B$10))) | AG25: =IF($Q25="","",IF($Q25="Tidak",1,0)) | AH25: =IF(ISNUMBER(AC25),Panduan_W6!$B$4,0)+IF(ISNUMBER(AD25),Panduan_W6!$B$5,0)+IF(ISNUMBER(AE25),Panduan_W6!$B$6,0)+IF(ISNUMBER(AF25),Panduan_W6!$B$7,0)+IF(ISNUMBER(AG25),Panduan_W6!$B$8,0) | AI25: =IF(LEFT(AJ25,7)<>"Lengkap","",IF(AJ25="Lengkap (gang)",AG25,(IF(ISNUMBER(AC25),Panduan_W6!$B$4*AC25,0)+IF(ISNUMBER(AD25),Panduan_W6!$B$5*AD25,0)+IF(ISNUMBER(AE25),Panduan_W6!$B$6*AE25,0)+IF(ISNUMBER(AF25),Panduan_W6!$B$7*AF25,0)+IF(ISNUMBER(AG25),Panduan_W6!$B$8*AG25,0))/AH25)) | AJ25: =IF(AND(Panduan_W6!$B$11="Ya",$I25="Gang",$J25="Sepi"),IF(ISNUMBER(AG25),"Lengkap (gang)","Belum lengkap"),IF(AND(ISNUMBER(AC25),ISNUMBER(AD25),ISNUMBER(AE25),ISNUMBER(AG25),OR(ISNUMBER(AF25),$K25="Tidak ada")),"Lengkap","Belum lengkap"))
A26: RUAS-025 | B26: Day 2 | C26: KWS-07 | D26: Theo | E26: 2026-08-17 | F26: 09:26 | G26: Jl.Ringroad Utara ( arah sebaliknya) | H26: 180.78 | I26: Jalan raya | J26: Ramai | K26: Tidak ada | L26: 0 | M26: 10.47 | N26: 0 | O26: tidak ada | P26: 0 | Q26: Ya | R26: 0 | S26: 0 | T26: 3 | U26: 0 | V26: 85 | W26: Di bawah 25 persen | X26: 179 | Y26: 2 | AA26: 3 | AB26: 1.01 | AC26: =IF($K26="","",IF($K26="Ada",1,IF($K26="Sebagian",0.5,0))) | AD26: =IF($K26="","",IF($K26="Tidak ada",0,IF($L26="","",MIN($L26/Panduan_W6!$B$9,1)))) | AE26: =IF($K26="","",IF($K26="Tidak ada",0,IF(OR($N26="",$H26=""),"",MAX(0,1-$N26/$H26)))) | AF26: =IF(OR($K26="",$K26="Tidak ada"),"",IF(OR($P26="",$H26=""),"",EXP(-$P26/$H26*100/Panduan_W6!$B$10))) | AG26: =IF($Q26="","",IF($Q26="Tidak",1,0)) | AH26: =IF(ISNUMBER(AC26),Panduan_W6!$B$4,0)+IF(ISNUMBER(AD26),Panduan_W6!$B$5,0)+IF(ISNUMBER(AE26),Panduan_W6!$B$6,0)+IF(ISNUMBER(AF26),Panduan_W6!$B$7,0)+IF(ISNUMBER(AG26),Panduan_W6!$B$8,0) | AI26: =IF(LEFT(AJ26,7)<>"Lengkap","",IF(AJ26="Lengkap (gang)",AG26,(IF(ISNUMBER(AC26),Panduan_W6!$B$4*AC26,0)+IF(ISNUMBER(AD26),Panduan_W6!$B$5*AD26,0)+IF(ISNUMBER(AE26),Panduan_W6!$B$6*AE26,0)+IF(ISNUMBER(AF26),Panduan_W6!$B$7*AF26,0)+IF(ISNUMBER(AG26),Panduan_W6!$B$8*AG26,0))/AH26)) | AJ26: =IF(AND(Panduan_W6!$B$11="Ya",$I26="Gang",$J26="Sepi"),IF(ISNUMBER(AG26),"Lengkap (gang)","Belum lengkap"),IF(AND(ISNUMBER(AC26),ISNUMBER(AD26),ISNUMBER(AE26),ISNUMBER(AG26),OR(ISNUMBER(AF26),$K26="Tidak ada")),"Lengkap","Belum lengkap"))
A27: RUAS-026 | B27: Day 2 | C27: KWS-07 | D27: Andalan | E27: 2026-08-17 | F27: 09:39 | G27: Gg. Pucung Baru 2, Depok | H27: 220 | I27: Gang | J27: Sepi | K27: Tidak ada | L27: 0 | M27: 4 | N27: 0 | O27: asap bakar sampah | P27: 1 | Q27: Ya | R27: 0 | S27: 0 | T27: 8 | U27: 1 | V27: 30 | W27: 25 sampai 50 persen | X27: 198 | Y27: 3 | Z27: ada rumah terbengkalai, di sampingnya langsung jurang/hutan, pembakaran sampah, dekat kantor padukuhan ngropoh | AA27: 1 | AB27: 1.11 | AC27: =IF($K27="","",IF($K27="Ada",1,IF($K27="Sebagian",0.5,0))) | AD27: =IF($K27="","",IF($K27="Tidak ada",0,IF($L27="","",MIN($L27/Panduan_W6!$B$9,1)))) | AE27: =IF($K27="","",IF($K27="Tidak ada",0,IF(OR($N27="",$H27=""),"",MAX(0,1-$N27/$H27)))) | AF27: =IF(OR($K27="",$K27="Tidak ada"),"",IF(OR($P27="",$H27=""),"",EXP(-$P27/$H27*100/Panduan_W6!$B$10))) | AG27: =IF($Q27="","",IF($Q27="Tidak",1,0)) | AH27: =IF(ISNUMBER(AC27),Panduan_W6!$B$4,0)+IF(ISNUMBER(AD27),Panduan_W6!$B$5,0)+IF(ISNUMBER(AE27),Panduan_W6!$B$6,0)+IF(ISNUMBER(AF27),Panduan_W6!$B$7,0)+IF(ISNUMBER(AG27),Panduan_W6!$B$8,0) | AI27: =IF(LEFT(AJ27,7)<>"Lengkap","",IF(AJ27="Lengkap (gang)",AG27,(IF(ISNUMBER(AC27),Panduan_W6!$B$4*AC27,0)+IF(ISNUMBER(AD27),Panduan_W6!$B$5*AD27,0)+IF(ISNUMBER(AE27),Panduan_W6!$B$6*AE27,0)+IF(ISNUMBER(AF27),Panduan_W6!$B$7*AF27,0)+IF(ISNUMBER(AG27),Panduan_W6!$B$8*AG27,0))/AH27)) | AJ27: =IF(AND(Panduan_W6!$B$11="Ya",$I27="Gang",$J27="Sepi"),IF(ISNUMBER(AG27),"Lengkap (gang)","Belum lengkap"),IF(AND(ISNUMBER(AC27),ISNUMBER(AD27),ISNUMBER(AE27),ISNUMBER(AG27),OR(ISNUMBER(AF27),$K27="Tidak ada")),"Lengkap","Belum lengkap"))
A28: RUAS-027 | B28: Day 2 | C28: KWS-07 | D28: Theo | E28: 2026-08-17 | F28: 09:51 | G28: Jl kaliwaru | H28: 229 | I28: Jalan kecil | J28: Sepi | K28: Tidak ada | M28: 3.7 | N28: 0 | O28: tidak ada | P28: 0 | Q28: Ya | R28: 0 | S28: 0 | T28: 4 | U28: 0 | V28: 40.79 | W28: Di bawah 25 persen | X28: 208 | Y28: 1 | Z28: jalan bagus Eko nya juga bagus | AA28: 1.5 | AB28: 1.1 | AC28: =IF($K28="","",IF($K28="Ada",1,IF($K28="Sebagian",0.5,0))) | AD28: =IF($K28="","",IF($K28="Tidak ada",0,IF($L28="","",MIN($L28/Panduan_W6!$B$9,1)))) | AE28: =IF($K28="","",IF($K28="Tidak ada",0,IF(OR($N28="",$H28=""),"",MAX(0,1-$N28/$H28)))) | AF28: =IF(OR($K28="",$K28="Tidak ada"),"",IF(OR($P28="",$H28=""),"",EXP(-$P28/$H28*100/Panduan_W6!$B$10))) | AG28: =IF($Q28="","",IF($Q28="Tidak",1,0)) | AH28: =IF(ISNUMBER(AC28),Panduan_W6!$B$4,0)+IF(ISNUMBER(AD28),Panduan_W6!$B$5,0)+IF(ISNUMBER(AE28),Panduan_W6!$B$6,0)+IF(ISNUMBER(AF28),Panduan_W6!$B$7,0)+IF(ISNUMBER(AG28),Panduan_W6!$B$8,0) | AI28: =IF(LEFT(AJ28,7)<>"Lengkap","",IF(AJ28="Lengkap (gang)",AG28,(IF(ISNUMBER(AC28),Panduan_W6!$B$4*AC28,0)+IF(ISNUMBER(AD28),Panduan_W6!$B$5*AD28,0)+IF(ISNUMBER(AE28),Panduan_W6!$B$6*AE28,0)+IF(ISNUMBER(AF28),Panduan_W6!$B$7*AF28,0)+IF(ISNUMBER(AG28),Panduan_W6!$B$8*AG28,0))/AH28)) | AJ28: =IF(AND(Panduan_W6!$B$11="Ya",$I28="Gang",$J28="Sepi"),IF(ISNUMBER(AG28),"Lengkap (gang)","Belum lengkap"),IF(AND(ISNUMBER(AC28),ISNUMBER(AD28),ISNUMBER(AE28),ISNUMBER(AG28),OR(ISNUMBER(AF28),$K28="Tidak ada")),"Lengkap","Belum lengkap"))
A29: RUAS-028 | B29: Day 2 | C29: KWS-08 | D29: Devon | E29: 2026-08-17 | F29: 10:03 | G29: Jl. Tajem Baru | H29: 82 | I29: Gang | J29: Sepi | K29: Tidak ada | L29: 0 | M29: 3 | N29: 0 | O29: tidak ada | P29: 0 | Q29: Ya | R29: 0 | S29: 0 | T29: 1 | U29: 0 | V29: 0 | W29: Di bawah 25 persen | X29: 84 | Y29: 2 | AA29: 1 | AB29: 0.98 | AC29: =IF($K29="","",IF($K29="Ada",1,IF($K29="Sebagian",0.5,0))) | AD29: =IF($K29="","",IF($K29="Tidak ada",0,IF($L29="","",MIN($L29/Panduan_W6!$B$9,1)))) | AE29: =IF($K29="","",IF($K29="Tidak ada",0,IF(OR($N29="",$H29=""),"",MAX(0,1-$N29/$H29)))) | AF29: =IF(OR($K29="",$K29="Tidak ada"),"",IF(OR($P29="",$H29=""),"",EXP(-$P29/$H29*100/Panduan_W6!$B$10))) | AG29: =IF($Q29="","",IF($Q29="Tidak",1,0)) | AH29: =IF(ISNUMBER(AC29),Panduan_W6!$B$4,0)+IF(ISNUMBER(AD29),Panduan_W6!$B$5,0)+IF(ISNUMBER(AE29),Panduan_W6!$B$6,0)+IF(ISNUMBER(AF29),Panduan_W6!$B$7,0)+IF(ISNUMBER(AG29),Panduan_W6!$B$8,0) | AI29: =IF(LEFT(AJ29,7)<>"Lengkap","",IF(AJ29="Lengkap (gang)",AG29,(IF(ISNUMBER(AC29),Panduan_W6!$B$4*AC29,0)+IF(ISNUMBER(AD29),Panduan_W6!$B$5*AD29,0)+IF(ISNUMBER(AE29),Panduan_W6!$B$6*AE29,0)+IF(ISNUMBER(AF29),Panduan_W6!$B$7*AF29,0)+IF(ISNUMBER(AG29),Panduan_W6!$B$8*AG29,0))/AH29)) | AJ29: =IF(AND(Panduan_W6!$B$11="Ya",$I29="Gang",$J29="Sepi"),IF(ISNUMBER(AG29),"Lengkap (gang)","Belum lengkap"),IF(AND(ISNUMBER(AC29),ISNUMBER(AD29),ISNUMBER(AE29),ISNUMBER(AG29),OR(ISNUMBER(AF29),$K29="Tidak ada")),"Lengkap","Belum lengkap"))
A30: RUAS-029 | B30: Day 2 | C30: KWS-08 | D30: Devon | E30: 2026-08-17 | F30: 10:10 | G30: Gg. Melati Jl. Tajem | H30: 163 | I30: Gang | J30: Sepi | K30: Tidak ada | L30: 0 | M30: 3 | N30: 0 | O30: tidak ada | P30: 0 | Q30: Ya | R30: 0 | S30: 0 | T30: 3 | U30: 0 | V30: 30 | W30: Di bawah 25 persen | X30: 150 | Y30: 4 | Z30: KOREKSI 2026-09-08 (disetujui pemilik repo): entri asli Lebar Jalan=0,0 dan Lebar Trotoar=3,0 saling tertukar. Lebar 0 m mustahil untuk gang yang muat satu mobil; 3,0 m wajar sebagai lebar gang, tidak wajar sebagai trotoar gang. W-6 tetap 0,0 karena Trotoar='Tidak ada'. Yang terpengaruh hanya W-5 tekanan lalu lintas. | AA30: 1 | AB30: 1.09 | AC30: =IF($K30="","",IF($K30="Ada",1,IF($K30="Sebagian",0.5,0))) | AD30: =IF($K30="","",IF($K30="Tidak ada",0,IF($L30="","",MIN($L30/Panduan_W6!$B$9,1)))) | AE30: =IF($K30="","",IF($K30="Tidak ada",0,IF(OR($N30="",$H30=""),"",MAX(0,1-$N30/$H30)))) | AF30: =IF(OR($K30="",$K30="Tidak ada"),"",IF(OR($P30="",$H30=""),"",EXP(-$P30/$H30*100/Panduan_W6!$B$10))) | AG30: =IF($Q30="","",IF($Q30="Tidak",1,0)) | AH30: =IF(ISNUMBER(AC30),Panduan_W6!$B$4,0)+IF(ISNUMBER(AD30),Panduan_W6!$B$5,0)+IF(ISNUMBER(AE30),Panduan_W6!$B$6,0)+IF(ISNUMBER(AF30),Panduan_W6!$B$7,0)+IF(ISNUMBER(AG30),Panduan_W6!$B$8,0) | AI30: =IF(LEFT(AJ30,7)<>"Lengkap","",IF(AJ30="Lengkap (gang)",AG30,(IF(ISNUMBER(AC30),Panduan_W6!$B$4*AC30,0)+IF(ISNUMBER(AD30),Panduan_W6!$B$5*AD30,0)+IF(ISNUMBER(AE30),Panduan_W6!$B$6*AE30,0)+IF(ISNUMBER(AF30),Panduan_W6!$B$7*AF30,0)+IF(ISNUMBER(AG30),Panduan_W6!$B$8*AG30,0))/AH30)) | AJ30: =IF(AND(Panduan_W6!$B$11="Ya",$I30="Gang",$J30="Sepi"),IF(ISNUMBER(AG30),"Lengkap (gang)","Belum lengkap"),IF(AND(ISNUMBER(AC30),ISNUMBER(AD30),ISNUMBER(AE30),ISNUMBER(AG30),OR(ISNUMBER(AF30),$K30="Tidak ada")),"Lengkap","Belum lengkap"))
A31: RUAS-030 | B31: Day 2 | C31: KWS-03 | D31: Andalan | E31: 2026-08-17 | F31: 10:40 | G31: Jl. Padjajaran depan UPN persis | H31: 220 | I31: Jalan kecil | J31: Sedang | K31: Tidak ada | L31: 0 | M31: 4 | N31: 0 | O31: tidak ada | P31: 1 | Q31: Ya | R31: 0 | S31: 0 | T31: 4 | U31: 0 | V31: 50 | W31: Di atas 50 persen | X31: 129 | Y31: 5 | Z31: rame, jalan pejalan kaki dibagi jadi aspal sama tanah. yang tanah full ditutupi pohon. gaada trotoar. | AA31: 1 | AB31: 1.71 | AC31: =IF($K31="","",IF($K31="Ada",1,IF($K31="Sebagian",0.5,0))) | AD31: =IF($K31="","",IF($K31="Tidak ada",0,IF($L31="","",MIN($L31/Panduan_W6!$B$9,1)))) | AE31: =IF($K31="","",IF($K31="Tidak ada",0,IF(OR($N31="",$H31=""),"",MAX(0,1-$N31/$H31)))) | AF31: =IF(OR($K31="",$K31="Tidak ada"),"",IF(OR($P31="",$H31=""),"",EXP(-$P31/$H31*100/Panduan_W6!$B$10))) | AG31: =IF($Q31="","",IF($Q31="Tidak",1,0)) | AH31: =IF(ISNUMBER(AC31),Panduan_W6!$B$4,0)+IF(ISNUMBER(AD31),Panduan_W6!$B$5,0)+IF(ISNUMBER(AE31),Panduan_W6!$B$6,0)+IF(ISNUMBER(AF31),Panduan_W6!$B$7,0)+IF(ISNUMBER(AG31),Panduan_W6!$B$8,0) | AI31: =IF(LEFT(AJ31,7)<>"Lengkap","",IF(AJ31="Lengkap (gang)",AG31,(IF(ISNUMBER(AC31),Panduan_W6!$B$4*AC31,0)+IF(ISNUMBER(AD31),Panduan_W6!$B$5*AD31,0)+IF(ISNUMBER(AE31),Panduan_W6!$B$6*AE31,0)+IF(ISNUMBER(AF31),Panduan_W6!$B$7*AF31,0)+IF(ISNUMBER(AG31),Panduan_W6!$B$8*AG31,0))/AH31)) | AJ31: =IF(AND(Panduan_W6!$B$11="Ya",$I31="Gang",$J31="Sepi"),IF(ISNUMBER(AG31),"Lengkap (gang)","Belum lengkap"),IF(AND(ISNUMBER(AC31),ISNUMBER(AD31),ISNUMBER(AE31),ISNUMBER(AG31),OR(ISNUMBER(AF31),$K31="Tidak ada")),"Lengkap","Belum lengkap"))
A32: RUAS-031 | B32: Day 2 | C32: KWS-08 | D32: Delon | E32: 2026-08-17 | F32: 10:53 | G32: Jl. Raya Tajem | H32: 104 | I32: Jalan raya | J32: Sedang | K32: Ada | L32: 2 | M32: 8 | N32: 18 | O32: tidak ada | P32: 3 | Q32: Ya | R32: 0 | S32: 0 | T32: 3 | U32: 0 | V32: 30 | W32: Nihil | X32: 107 | Y32: 2 | Z32: jalan melebar, memotong area pejalan kaki, area pejalan kaki penuh batu dan pasir | AA32: 4 | AB32: 0.97 | AC32: =IF($K32="","",IF($K32="Ada",1,IF($K32="Sebagian",0.5,0))) | AD32: =IF($K32="","",IF($K32="Tidak ada",0,IF($L32="","",MIN($L32/Panduan_W6!$B$9,1)))) | AE32: =IF($K32="","",IF($K32="Tidak ada",0,IF(OR($N32="",$H32=""),"",MAX(0,1-$N32/$H32)))) | AF32: =IF(OR($K32="",$K32="Tidak ada"),"",IF(OR($P32="",$H32=""),"",EXP(-$P32/$H32*100/Panduan_W6!$B$10))) | AG32: =IF($Q32="","",IF($Q32="Tidak",1,0)) | AH32: =IF(ISNUMBER(AC32),Panduan_W6!$B$4,0)+IF(ISNUMBER(AD32),Panduan_W6!$B$5,0)+IF(ISNUMBER(AE32),Panduan_W6!$B$6,0)+IF(ISNUMBER(AF32),Panduan_W6!$B$7,0)+IF(ISNUMBER(AG32),Panduan_W6!$B$8,0) | AI32: =IF(LEFT(AJ32,7)<>"Lengkap","",IF(AJ32="Lengkap (gang)",AG32,(IF(ISNUMBER(AC32),Panduan_W6!$B$4*AC32,0)+IF(ISNUMBER(AD32),Panduan_W6!$B$5*AD32,0)+IF(ISNUMBER(AE32),Panduan_W6!$B$6*AE32,0)+IF(ISNUMBER(AF32),Panduan_W6!$B$7*AF32,0)+IF(ISNUMBER(AG32),Panduan_W6!$B$8*AG32,0))/AH32)) | AJ32: =IF(AND(Panduan_W6!$B$11="Ya",$I32="Gang",$J32="Sepi"),IF(ISNUMBER(AG32),"Lengkap (gang)","Belum lengkap"),IF(AND(ISNUMBER(AC32),ISNUMBER(AD32),ISNUMBER(AE32),ISNUMBER(AG32),OR(ISNUMBER(AF32),$K32="Tidak ada")),"Lengkap","Belum lengkap"))
A33: RUAS-032 | B33: Day 2 | C33: KWS-08 | D33: Devon | E33: 2026-08-17 | F33: 11:04 | G33: Jl. Kadisoka | H33: 110 | I33: Jalan raya | J33: Ramai | K33: Ada | L33: 1 | M33: 5 | N33: 0 | O33: pedagang kaki lima | P33: 1 | Q33: Ya | R33: 0 | S33: 0 | T33: 0 | U33: 0 | V33: 0 | W33: Di bawah 25 persen | X33: 90 | Y33: 2 | Z33: tidak ramah penalan kaki. Terdapat lobang parit ditengah are jalan. | AA33: 2 | AB33: 1.22 | AC33: =IF($K33="","",IF($K33="Ada",1,IF($K33="Sebagian",0.5,0))) | AD33: =IF($K33="","",IF($K33="Tidak ada",0,IF($L33="","",MIN($L33/Panduan_W6!$B$9,1)))) | AE33: =IF($K33="","",IF($K33="Tidak ada",0,IF(OR($N33="",$H33=""),"",MAX(0,1-$N33/$H33)))) | AF33: =IF(OR($K33="",$K33="Tidak ada"),"",IF(OR($P33="",$H33=""),"",EXP(-$P33/$H33*100/Panduan_W6!$B$10))) | AG33: =IF($Q33="","",IF($Q33="Tidak",1,0)) | AH33: =IF(ISNUMBER(AC33),Panduan_W6!$B$4,0)+IF(ISNUMBER(AD33),Panduan_W6!$B$5,0)+IF(ISNUMBER(AE33),Panduan_W6!$B$6,0)+IF(ISNUMBER(AF33),Panduan_W6!$B$7,0)+IF(ISNUMBER(AG33),Panduan_W6!$B$8,0) | AI33: =IF(LEFT(AJ33,7)<>"Lengkap","",IF(AJ33="Lengkap (gang)",AG33,(IF(ISNUMBER(AC33),Panduan_W6!$B$4*AC33,0)+IF(ISNUMBER(AD33),Panduan_W6!$B$5*AD33,0)+IF(ISNUMBER(AE33),Panduan_W6!$B$6*AE33,0)+IF(ISNUMBER(AF33),Panduan_W6!$B$7*AF33,0)+IF(ISNUMBER(AG33),Panduan_W6!$B$8*AG33,0))/AH33)) | AJ33: =IF(AND(Panduan_W6!$B$11="Ya",$I33="Gang",$J33="Sepi"),IF(ISNUMBER(AG33),"Lengkap (gang)","Belum lengkap"),IF(AND(ISNUMBER(AC33),ISNUMBER(AD33),ISNUMBER(AE33),ISNUMBER(AG33),OR(ISNUMBER(AF33),$K33="Tidak ada")),"Lengkap","Belum lengkap"))
A34: RUAS-033 | B34: Day 2 | C34: KWS-08 | D34: Delon | E34: 2026-08-17 | F34: 11:10 | G34: Jl. Raya Tajem | H34: 125 | I34: Jalan raya | J34: Sedang | K34: Ada | L34: 1 | M34: 10 | N34: 3 | O34: pedagang kaki lima | P34: 0 | Q34: Ya | R34: 0 | S34: 0 | T34: 3 | U34: 0 | V34: 41 | W34: Di bawah 25 persen | X34: 123 | Y34: 2 | Z34: area pejalan kaki cukup untuk 1 orang banyak pertokoan, jalanab ramai melaku kencang, beberapa bagian pejalan tertutup pedagang kaki lima | AA34: 4 | AB34: 1.02 | AC34: =IF($K34="","",IF($K34="Ada",1,IF($K34="Sebagian",0.5,0))) | AD34: =IF($K34="","",IF($K34="Tidak ada",0,IF($L34="","",MIN($L34/Panduan_W6!$B$9,1)))) | AE34: =IF($K34="","",IF($K34="Tidak ada",0,IF(OR($N34="",$H34=""),"",MAX(0,1-$N34/$H34)))) | AF34: =IF(OR($K34="",$K34="Tidak ada"),"",IF(OR($P34="",$H34=""),"",EXP(-$P34/$H34*100/Panduan_W6!$B$10))) | AG34: =IF($Q34="","",IF($Q34="Tidak",1,0)) | AH34: =IF(ISNUMBER(AC34),Panduan_W6!$B$4,0)+IF(ISNUMBER(AD34),Panduan_W6!$B$5,0)+IF(ISNUMBER(AE34),Panduan_W6!$B$6,0)+IF(ISNUMBER(AF34),Panduan_W6!$B$7,0)+IF(ISNUMBER(AG34),Panduan_W6!$B$8,0) | AI34: =IF(LEFT(AJ34,7)<>"Lengkap","",IF(AJ34="Lengkap (gang)",AG34,(IF(ISNUMBER(AC34),Panduan_W6!$B$4*AC34,0)+IF(ISNUMBER(AD34),Panduan_W6!$B$5*AD34,0)+IF(ISNUMBER(AE34),Panduan_W6!$B$6*AE34,0)+IF(ISNUMBER(AF34),Panduan_W6!$B$7*AF34,0)+IF(ISNUMBER(AG34),Panduan_W6!$B$8*AG34,0))/AH34)) | AJ34: =IF(AND(Panduan_W6!$B$11="Ya",$I34="Gang",$J34="Sepi"),IF(ISNUMBER(AG34),"Lengkap (gang)","Belum lengkap"),IF(AND(ISNUMBER(AC34),ISNUMBER(AD34),ISNUMBER(AE34),ISNUMBER(AG34),OR(ISNUMBER(AF34),$K34="Tidak ada")),"Lengkap","Belum lengkap"))
A35: RUAS-034 | B35: Day 2 | C35: KWS-03 | D35: Andalan | E35: 2026-08-17 | F35: 11:27 | G35: Jl. UPN | H35: 140 | I35: Jalan kecil | J35: Sepi | K35: Sebagian | L35: 1 | M35: 3 | N35: 0 | O35: tiang listrik | P35: 2 | Q35: Ya | R35: 0 | S35: 0 | T35: 6 | U35: 0 | V35: 16 | W35: Di bawah 25 persen | X35: 120 | Y35: 2 | Z35: gang persis di samping UPN, ada warmindo dan kos. terhalang bekas bakar sampah, jalannya kecil dan cukup bersampah || KOREKSI 2026-09-08 (disetujui pemilik repo): entri asli Trotoar='Tidak ada' tapi Lebar Trotoar=1,0 m - bertentangan. Diubah jadi 'Sebagian'. DASAR: keputusan pemilik repo, bukan nilai tercatat. PERHATIAN: catatan lapangan di atas menggambarkan gang kecil bersampah yang terhalang bekas bakar sampah, dan kolom 'Pejalan turun ke jalan'='Ya' - keduanya TIDAK mendukung adanya trotoar layak. Perlu ditinjau ulang pencatat. | AA35: 1 | AB35: 1.17 | AC35: =IF($K35="","",IF($K35="Ada",1,IF($K35="Sebagian",0.5,0))) | AD35: =IF($K35="","",IF($K35="Tidak ada",0,IF($L35="","",MIN($L35/Panduan_W6!$B$9,1)))) | AE35: =IF($K35="","",IF($K35="Tidak ada",0,IF(OR($N35="",$H35=""),"",MAX(0,1-$N35/$H35)))) | AF35: =IF(OR($K35="",$K35="Tidak ada"),"",IF(OR($P35="",$H35=""),"",EXP(-$P35/$H35*100/Panduan_W6!$B$10))) | AG35: =IF($Q35="","",IF($Q35="Tidak",1,0)) | AH35: =IF(ISNUMBER(AC35),Panduan_W6!$B$4,0)+IF(ISNUMBER(AD35),Panduan_W6!$B$5,0)+IF(ISNUMBER(AE35),Panduan_W6!$B$6,0)+IF(ISNUMBER(AF35),Panduan_W6!$B$7,0)+IF(ISNUMBER(AG35),Panduan_W6!$B$8,0) | AI35: =IF(LEFT(AJ35,7)<>"Lengkap","",IF(AJ35="Lengkap (gang)",AG35,(IF(ISNUMBER(AC35),Panduan_W6!$B$4*AC35,0)+IF(ISNUMBER(AD35),Panduan_W6!$B$5*AD35,0)+IF(ISNUMBER(AE35),Panduan_W6!$B$6*AE35,0)+IF(ISNUMBER(AF35),Panduan_W6!$B$7*AF35,0)+IF(ISNUMBER(AG35),Panduan_W6!$B$8*AG35,0))/AH35)) | AJ35: =IF(AND(Panduan_W6!$B$11="Ya",$I35="Gang",$J35="Sepi"),IF(ISNUMBER(AG35),"Lengkap (gang)","Belum lengkap"),IF(AND(ISNUMBER(AC35),ISNUMBER(AD35),ISNUMBER(AE35),ISNUMBER(AG35),OR(ISNUMBER(AF35),$K35="Tidak ada")),"Lengkap","Belum lengkap"))
A36: RUAS-035 | B36: Day 2 | C36: KWS-03 | D36: Theo | E36: 2026-08-17 | F36: 11:46 | G36: JL. Padjajaran | H36: 108.7 | I36: Jalan raya | J36: Ramai | K36: Tidak ada | L36: 0 | M36: 12 | N36: 0 | O36: tidak ada | P36: 0 | Q36: Ya | R36: 0 | S36: 0 | T36: 3 | U36: 0 | V36: 44.5 | W36: 25 sampai 50 persen | X36: 105 | Y36: 2 | AA36: 3 | AB36: 1.04 | AC36: =IF($K36="","",IF($K36="Ada",1,IF($K36="Sebagian",0.5,0))) | AD36: =IF($K36="","",IF($K36="Tidak ada",0,IF($L36="","",MIN($L36/Panduan_W6!$B$9,1)))) | AE36: =IF($K36="","",IF($K36="Tidak ada",0,IF(OR($N36="",$H36=""),"",MAX(0,1-$N36/$H36)))) | AF36: =IF(OR($K36="",$K36="Tidak ada"),"",IF(OR($P36="",$H36=""),"",EXP(-$P36/$H36*100/Panduan_W6!$B$10))) | AG36: =IF($Q36="","",IF($Q36="Tidak",1,0)) | AH36: =IF(ISNUMBER(AC36),Panduan_W6!$B$4,0)+IF(ISNUMBER(AD36),Panduan_W6!$B$5,0)+IF(ISNUMBER(AE36),Panduan_W6!$B$6,0)+IF(ISNUMBER(AF36),Panduan_W6!$B$7,0)+IF(ISNUMBER(AG36),Panduan_W6!$B$8,0) | AI36: =IF(LEFT(AJ36,7)<>"Lengkap","",IF(AJ36="Lengkap (gang)",AG36,(IF(ISNUMBER(AC36),Panduan_W6!$B$4*AC36,0)+IF(ISNUMBER(AD36),Panduan_W6!$B$5*AD36,0)+IF(ISNUMBER(AE36),Panduan_W6!$B$6*AE36,0)+IF(ISNUMBER(AF36),Panduan_W6!$B$7*AF36,0)+IF(ISNUMBER(AG36),Panduan_W6!$B$8*AG36,0))/AH36)) | AJ36: =IF(AND(Panduan_W6!$B$11="Ya",$I36="Gang",$J36="Sepi"),IF(ISNUMBER(AG36),"Lengkap (gang)","Belum lengkap"),IF(AND(ISNUMBER(AC36),ISNUMBER(AD36),ISNUMBER(AE36),ISNUMBER(AG36),OR(ISNUMBER(AF36),$K36="Tidak ada")),"Lengkap","Belum lengkap"))
A37: RUAS-036 | B37: Day 2 | C37: KWS-03 | D37: Theo | E37: 2026-08-17 | F37: 12:01 | G37: Jl. perumnas | H37: 193 | I37: Jalan kecil | J37: Ramai | K37: Tidak ada | L37: 0 | M37: 5.6 | N37: 0 | O37: lainnya | P37: 5 | Q37: Ya | R37: 2 | S37: 0 | T37: 4 | U37: 0 | V37: 49.28 | W37: Di bawah 25 persen | X37: 156 | Y37: 2 | AA37: 2 | AB37: 1.24 | AC37: =IF($K37="","",IF($K37="Ada",1,IF($K37="Sebagian",0.5,0))) | AD37: =IF($K37="","",IF($K37="Tidak ada",0,IF($L37="","",MIN($L37/Panduan_W6!$B$9,1)))) | AE37: =IF($K37="","",IF($K37="Tidak ada",0,IF(OR($N37="",$H37=""),"",MAX(0,1-$N37/$H37)))) | AF37: =IF(OR($K37="",$K37="Tidak ada"),"",IF(OR($P37="",$H37=""),"",EXP(-$P37/$H37*100/Panduan_W6!$B$10))) | AG37: =IF($Q37="","",IF($Q37="Tidak",1,0)) | AH37: =IF(ISNUMBER(AC37),Panduan_W6!$B$4,0)+IF(ISNUMBER(AD37),Panduan_W6!$B$5,0)+IF(ISNUMBER(AE37),Panduan_W6!$B$6,0)+IF(ISNUMBER(AF37),Panduan_W6!$B$7,0)+IF(ISNUMBER(AG37),Panduan_W6!$B$8,0) | AI37: =IF(LEFT(AJ37,7)<>"Lengkap","",IF(AJ37="Lengkap (gang)",AG37,(IF(ISNUMBER(AC37),Panduan_W6!$B$4*AC37,0)+IF(ISNUMBER(AD37),Panduan_W6!$B$5*AD37,0)+IF(ISNUMBER(AE37),Panduan_W6!$B$6*AE37,0)+IF(ISNUMBER(AF37),Panduan_W6!$B$7*AF37,0)+IF(ISNUMBER(AG37),Panduan_W6!$B$8*AG37,0))/AH37)) | AJ37: =IF(AND(Panduan_W6!$B$11="Ya",$I37="Gang",$J37="Sepi"),IF(ISNUMBER(AG37),"Lengkap (gang)","Belum lengkap"),IF(AND(ISNUMBER(AC37),ISNUMBER(AD37),ISNUMBER(AE37),ISNUMBER(AG37),OR(ISNUMBER(AF37),$K37="Tidak ada")),"Lengkap","Belum lengkap"))
A38: RUAS-037 | B38: Day 2 | C38: KWS-03 | D38: Theo | E38: 2026-08-17 | F38: 12:10 | G38: JL. upn (bagian belakang) | H38: 85.3 | I38: Jalan kecil | J38: Sepi | K38: Tidak ada | L38: 0 | M38: 3.7 | N38: 0 | O38: tidak ada | P38: 1 | Q38: Ya | R38: 0 | S38: 0 | T38: 0 | U38: 0 | W38: Di atas 50 persen | X38: 65 | Y38: 2 | Z38: lapangan sepak bola luas, gaada lampu, tapi teduh | AA38: 2 | AB38: 1.31 | AC38: =IF($K38="","",IF($K38="Ada",1,IF($K38="Sebagian",0.5,0))) | AD38: =IF($K38="","",IF($K38="Tidak ada",0,IF($L38="","",MIN($L38/Panduan_W6!$B$9,1)))) | AE38: =IF($K38="","",IF($K38="Tidak ada",0,IF(OR($N38="",$H38=""),"",MAX(0,1-$N38/$H38)))) | AF38: =IF(OR($K38="",$K38="Tidak ada"),"",IF(OR($P38="",$H38=""),"",EXP(-$P38/$H38*100/Panduan_W6!$B$10))) | AG38: =IF($Q38="","",IF($Q38="Tidak",1,0)) | AH38: =IF(ISNUMBER(AC38),Panduan_W6!$B$4,0)+IF(ISNUMBER(AD38),Panduan_W6!$B$5,0)+IF(ISNUMBER(AE38),Panduan_W6!$B$6,0)+IF(ISNUMBER(AF38),Panduan_W6!$B$7,0)+IF(ISNUMBER(AG38),Panduan_W6!$B$8,0) | AI38: =IF(LEFT(AJ38,7)<>"Lengkap","",IF(AJ38="Lengkap (gang)",AG38,(IF(ISNUMBER(AC38),Panduan_W6!$B$4*AC38,0)+IF(ISNUMBER(AD38),Panduan_W6!$B$5*AD38,0)+IF(ISNUMBER(AE38),Panduan_W6!$B$6*AE38,0)+IF(ISNUMBER(AF38),Panduan_W6!$B$7*AF38,0)+IF(ISNUMBER(AG38),Panduan_W6!$B$8*AG38,0))/AH38)) | AJ38: =IF(AND(Panduan_W6!$B$11="Ya",$I38="Gang",$J38="Sepi"),IF(ISNUMBER(AG38),"Lengkap (gang)","Belum lengkap"),IF(AND(ISNUMBER(AC38),ISNUMBER(AD38),ISNUMBER(AE38),ISNUMBER(AG38),OR(ISNUMBER(AF38),$K38="Tidak ada")),"Lengkap","Belum lengkap"))
